Workbook

Sheet Config
A1: type | B1: name | C1: value | D1: 설명
A2: boolean | B2: CONFIG_DEBUG | C2: false
A3: real | B3: CONFIG_MAX_X | C3: 10240
A4: real | B4: CONFIG_MIN_X | C4: -10240
A5: real | B5: CONFIG_MAX_Y | C5: 10240
A6: real | B6: CONFIG_MIN_Y | C6: -10240
A7: integer | B7: CONFIG_CLIFF_HEIGHT_DEFAULT | C7: 2
A8: player | B8: CONFIG_PLAYER_ITEM | C8: Player(22) | D8: 아이템 더미유닛 출력 시
A9: player | B9: CONFIG_PLAYER_UNDEAD | C9: Player(20) | D9: 언데드
A10: player | B10: CONFIG_PLAYER_MONSTER | C10: Player(23) | D10: 괴수
A11: player | B11: CONFIG_PLAYER_GUARDIANS | C11: Player(21) | D11: 수호자
A12: player | B12: CONFIG_PLAYER_SYSTEM | C12: Player(24) | D12: 시스템메세지
A13: player | B13: CONFIG_PLAYER_NPC | C13: Player(PLAYER_NEUTRAL_PASSIVE) | D13: NPC
A14: integer | B14: CONFIG_PLAYER_MAX | C14: 4
A15: real | B15: CONFIG_UNIT_SELECTION_CIRCLE_DEFAULT | C15: 1.25
A16: real | B16: CONFIG_UNIT_ATTACK_RANGE_DEFAULT | C16: 100
A17: real | B17: CONFIG_UNIT_ATTACK_DELAY_DEFAULT | C17: 1.5
A18: integer | B18: CONFIG_ABILITY_SIZE | C18: 10 | D18: 보유 어빌리티 한도
A19: integer | B19: CONFIG_ABILITY_ID_ATTACK_SPEED | C19: 'Axx0' | D19: 공격속도 스킬
A20: integer | B20: CONFIG_ABILITY_ID_FOLLOW | C20: 'Axx1' | D20: 따라가기(채널) 스킬
A21: integer | B21: CONFIG_ABILITY_ID_MOVE | C21: 'Axx2' | D21: 이동하기(채널) 스킬
A22: integer | B22: CONFIG_ABILITY_ID_INTERACT | C22: 'Axx4' | D22: 상호작용(채널) 스킬
A23: integer | B23: CONFIG_ABILITY_ID_CLASS_INTERACTIVE | C23: 'Axx6' | D23: 상호작용 유닛이 가지는 더미스킬
A24: integer | B24: CONFIG_ABILITY_ID_STOP | C24: 'Axx7' | D24: 멈추기(채널) 스킬, 자동공격 방지용으로 만든듯
A25: integer | B25: CONFIG_ABILITY_ID_CLASS_NONUNIT | C25: 'Axx8' | D25: 유닛(wrapper)이 아닌 유닛이 가지는 더미스킬
A26: string | B26: CONFIG_ORDER_STRING_FOLLOW | C26: channel | D26: 따라가기 명령문자열
A27: string | B27: CONFIG_ORDER_STRING_CUSTOM_MOVE | C27: acolyteharvest | D27: 이동하기(채널) 명령문자열
A28: string | B28: CONFIG_ORDER_STRING_INTERACT | C28: absorb | D28: 상호작용하기 명령문자열
A29: string | B29: CONFIG_ORDER_STRING_CUSTOM_STOP | C29: acidbomb | D29: 멈추기 명령문자열
A30: integer | B30: CONFIG_UNIT_INVENTORY_SIZE | C30: 4/*6*/ | D30: 유닛 인벤토리 사이즈(아티팩트 시스템 폐기돼서 안쓰고있음)
A31: integer | B31: CONFIG_FRAME_MAX_LEVEL | C31: 32 | D31: 프레임 뎁스 최대값(똑부러지게 정한 값이 아니고 널널하게 잡음)
A32: integer | B32: CONFIG_FRAME_LEVEL_BASIC | C32: 0 | D32: 기본프레임
A33: integer | B33: CONFIG_FRAME_LEVEL_WINDOW | C33: 1 | D33: 창(단축키, 인벤 등)
A34: integer | B34: CONFIG_FRAME_LEVEL_CASTBAR | C34: 2 | D34: 캐스트바
A35: integer | B35: CONFIG_FRAME_LEVEL_MINIMAP | C35: 3 | D35: 미니맵
A36: integer | B36: CONFIG_FRAME_LEVEL_TOOLTIP | C36: 4 | D36: 툴팁(어빌리티)
A37: integer | B37: CONFIG_FRAME_LEVEL_POPUP | C37: 5 | D37: 팝업
A38: integer | B38: CONFIG_MINIMAP_OFFSET_X | C38: 0
A39: integer | B39: CONFIG_MINIMAP_OFFSET_Y | C39: 16
A40: integer | B40: CONFIG_MINIMAP_SIZE | C40: 240
...

Sheet Enum
A1: type | B1: name | C1: value | D1: description | E1: ?
A2: integer | B2: ENUM_OBJECT_TYPE_UNIT | C2: 1
A3: integer | B3: ENUM_OBJECT_TYPE_INTERACTIVE | C3: 2
A4: integer | B4: ENUM_UNIT_ARMOR_TYPE_WHOKNOWS | C4: 0 | D4: 피격음 없음
A5: integer | B5: ENUM_UNIT_ARMOR_TYPE_FLESH | C5: 1 | D5: 살점
A6: integer | B6: ENUM_UNIT_ARMOR_TYPE_METAL | C6: 2 | D6: 금속
A7: integer | B7: ENUM_UNIT_ARMOR_TYPE_WOOD | C7: 3 | D7: 나무
A8: integer | B8: ENUM_UNIT_ARMOR_TYPE_ETHREAL | C8: 4 | D8: 이더리얼
A9: integer | B9: ENUM_UNIT_ARMOR_TYPE_STONE | C9: 5 | D9: 돌
A10: integer | B10: ENUM_STAT_MAXHP | C10: 0 | D10: 최대체력
A11: integer | B11: ENUM_STAT_MAXMP | C11: 1 | D11: 최대마나
A12: integer | B12: ENUM_STAT_ATTACK | C12: 2 | D12: 공격력
A13: integer | B13: ENUM_STAT_DEFENSE | C13: 3 | D13: 방어력
A14: integer | B14: ENUM_STAT_MAGICPOWER | C14: 4 | D14: 주문력
A15: integer | B15: ENUM_STAT_RESISTANCE | C15: 5 | D15: 저항력
... A27: integer | B27: ENUM_STAT_HEAL_AMP | C27: 17 | D27: 받는회복증폭
A28: integer | B28: ENUM_STAT_RODONG | C28: 18 | D28: 노동력
A29: integer | B29: ENUM_STAT_LOVE | C29: 19 | D29: 매력(애정)
A30: integer | B30: ENUM_STAT_GREED | C30: 20 | D30: 탐욕
A31: integer | B31: ENUM_STAT_INSIGHT | C31: 21 | D31: 통찰
A32: integer | B32: ENUM_STAT_SIZE | C32: 22//E | D32: 배열크기
A33: integer | B33: ENUM_STAT_UNIT_LEVEL | C33: 100 | D33: 유닛의 레벨
A34: integer | B34: ENUM_STAT_SKILL_LEVEL | C34: 101 | D34: 어빌리티 레벨
A35: integer | B35: ENUM_STAT_COOLDOWN | C35: 102 | D35: 재사용 대기시간
A36: integer | B36: ENUM_STAT_SUMMON_DURATION | C36: 102 | D36: 소환시간
A37: integer | B37: ENUM_STAT_CONSTANT | C37: 103 | D37: 상수값 하이라이팅 색상
A38: integer | B38: ENUM_STAT_PHYSICAL | C38: 103 | D38: 물리피해
A39: integer | B39: ENUM_STAT_MAGICAL | C39: 104 | D39: 마법피해
A40: integer | B40: ENUM_STAT_HP | C40: 105 | D40: 체력
A41: integer | B41: ENUM_STAT_MP | C41: 104 | D41: 마나
A42: integer | B42: ENUM_STAT_HP_LOST | C42: 106 | D42: 잃은체력
A43: integer | B43: ENUM_STAT_MP_LOST | C43: 107 | D43: 잃은마나
A44: integer | B44: ENUM_STAT_HP_CURRENT | C44: 105 | D44: 남은체력
A45: integer | B45: ENUM_STAT_MP_CURRENT | C45: 108 | D45: 남은마나
A46: integer | B46: ENUM_STAT_SHIELD | C46: 109 | D46: 보호막
A47: integer | B47: ENUM_STAT_GOLD | C47: 106 | D47: 금 보유량
A48: integer | B48: ENUM_STAT_INDEX_BASE | C48: 0 | D48: 기본값
A49: integer | B49: ENUM_STAT_INDEX_LEVEL | C49: 1 | D49: 레벨당
A50: integer | B50: ENUM_STAT_INDEX_MULTIPLY | C50: 2 | D50: 곱하기값
A51: integer | B51: ENUM_STAT_INDEX_DIVIDE | C51: 3 | D51: 나누기값
...

Sheet EnumLookup
A1: index | B1: arrname | C1: subfix | D1: type | E1: value | F1: subfix | G1: type | H1: value | I1: subfix | J1: type | K1: value
A2: ENUM_STAT_MAXHP | B2: CONSTANT_STAT | C2: NAME | D2: string | E2: 최대체력 | F2: COLOR | G2: string | H2: |cff00ff00 | I2: ICON | J2: string | K2: Icons\\tooltips\\stat_hp.blp
A3: ENUM_STAT_MAXMP | B3: CONSTANT_STAT | C3: NAME | D3: string | E3: 최대마나 | F3: COLOR | G3: string | H3: |cff0099ff | I3: ICON | J3: string | K3: Icons\\tooltips\\stat_mp.blp
A4: ENUM_STAT_ATTACK | B4: CONSTANT_STAT | C4: NAME | D4: string | E4: 공격력 | F4: COLOR | G4: string | H4: |cffff9900 | I4: ICON | J4: string | K4: Icons\\tooltips\\stat_attack.blp
A5: ENUM_STAT_DEFENSE | B5: CONSTANT_STAT | C5: NAME | D5: string | E5: 방어력 | F5: COLOR | G5: string | H5: |cffffcc99 | I5: ICON | J5: string | K5: Icons\\tooltips\\stat_defense.blp
A6: ENUM_STAT_MAGICPOWER | B6: CONSTANT_STAT | C6: NAME | D6: string | E6: 주문력 | F6: COLOR | G6: string | H6: |cff9999ff | I6: ICON | J6: string | K6: Icons\\tooltips\\stat_magicpower.blp
A7: ENUM_STAT_RESISTANCE | B7: CONSTANT_STAT | C7: NAME | D7: string | E7: 저항력 | F7: COLOR | G7: string | H7: |cff00ff99 | I7: ICON | J7: string | K7: Icons\\tooltips\\stat_resistance.blp
A8: ENUM_STAT_ACCURACY | B8: CONSTANT_STAT | C8: NAME | D8: string | E8: 정확도 | F8: COLOR | G8: string | H8: |cffff00ff | I8: ICON | J8: string | K8: Icons\\tooltips\\stat_accuracy.blp
A9: ENUM_STAT_EVASION | B9: CONSTANT_STAT | C9: NAME | D9: string | E9: 회피치 | F9: COLOR | G9: string | H9: |cff99ccff | I9: ICON | J9: string | K9: Icons\\tooltips\\stat_evasion.blp
A10: ENUM_STAT_ARMOR_PENET | B10: CONSTANT_STAT | C10: NAME | D10: string | E10: 방어관통 | F10: COLOR | G10: string | H10: |cffff6600 | I10: ICON | J10: string | K10: Icons\\tooltips\\stat_armorpenet.blp
A11: ENUM_STAT_MAGIC_PENET | B11: CONSTANT_STAT | C11: NAME | D11: string | E11: 저항관통 | F11: COLOR | G11: string | H11: |cff9999dd | I11: ICON | J11: string | K11: Icons\\tooltips\\stat_magicpenet.blp
A12: ENUM_STAT_SPELL_BOOST | B12: CONSTANT_STAT | C12: NAME | D12: string | E12: 스킬가속 | F12: COLOR | G12: string | H12: |cffff99ff | I12: ICON | J12: string | K12: Icons\\tooltips\\stat_spellboost.blp
... A27: ENUM_STAT_SUMMON_DURATION | B27: CONSTANT_STAT | C27: NAME | D27: string | E27: 소환 지속시간 | F27: COLOR | G27: string | H27: |cffc3dbff | I27: ICON | J27: string | K27: Icons\\tooltips\\tooltip_summonduration.blp
A28: ENUM_STAT_CONSTANT | B28: CONSTANT_STAT | C28: NAME | D28: string | E28: 고정값 | F28: COLOR | G28: string | H28: |cffffffff
A29: ENUM_STAT_PHYSICAL | B29: CONSTANT_STAT | C29: NAME | D29: string | E29: 물리 | F29: COLOR | G29: string | H29: |cffff9900
A30: ENUM_STAT_MAGICAL | B30: CONSTANT_STAT | C30: NAME | D30: string | E30: 마법 | F30: COLOR | G30: string | H30: |cff9999ff
A31: ENUM_STAT_HP | B31: CONSTANT_STAT | C31: NAME | D31: string | E31: 체력 | F31: COLOR | G31: string | H31: |cff00ff00
A32: ENUM_STAT_MP | B32: CONSTANT_STAT | C32: NAME | D32: string | E32: 마나 | F32: COLOR | G32: string | H32: |cff0099ff
A33: ENUM_STAT_HP_LOST | B33: CONSTANT_STAT | C33: NAME | D33: string | E33: 잃은 체력 | F33: COLOR | G33: string | H33: |cffff3333
A34: ENUM_STAT_MP_LOST | B34: CONSTANT_STAT | C34: NAME | D34: string | E34: 잃은 마나 | F34: COLOR | G34: string | H34: |cff0099ff
A35: ENUM_STAT_HP_CURRENT | B35: CONSTANT_STAT | C35: NAME | D35: string | E35: 현재 체력 | F35: COLOR | G35: string | H35: |cff00ff00
A36: ENUM_STAT_MP_CURRENT | B36: CONSTANT_STAT | C36: NAME | D36: string | E36: 현재 마나 | F36: COLOR | G36: string | H36: |cff0099ff
A37: ENUM_STAT_SHIELD | B37: CONSTANT_STAT | C37: NAME | D37: string | E37: 보호막 | F37: COLOR | G37: string | H37: |cffc690e1
A38: ENUM_STAT_GOLD | B38: CONSTANT_STAT | C38: NAME | D38: string | E38: 금화 | F38: COLOR | G38: string | H38: |cffffcc00
A39: ENUM_STATUS_STUN | B39: CONSTANT_STATUS | C39: NAME | D39: string | E39: 기절 | F39: COLOR | G39: string | H39: |cff00ffff
... A77: ENUM_DAMAGE_UNDEFINED | B77: CONSTANT_DAMAGE | C77: NAME | D77: string | E77: 미분류 | F77: COLOR | G77: string | H77: |cff999999
A78: ENUM_TIER_0 | B78: CONSTANT_TIER | C78: NAME | D78: string | F78: COLOR | G78: string | H78: |cffcccccc
A79: ENUM_TIER_1 | B79: CONSTANT_TIER | C79: NAME | D79: string | E79: 1티어 | F79: COLOR | G79: string | H79: |cffffffff
A80: ENUM_TIER_2 | B80: CONSTANT_TIER | C80: NAME | D80: string | E80: 2티어 | F80: COLOR | G80: string | H80: |cff00ff00
A81: ENUM_TIER_3 | B81: CONSTANT_TIER | C81: NAME | D81: string | E81: 3티어 | F81: COLOR | G81: string | H81: |cff0099ff
A82: ENUM_TIER_4 | B82: CONSTANT_TIER | C82: NAME | D82: string | E82: 4티어 | F82: COLOR | G82: string | H82: |cffcc00ff
A83: ENUM_TIER_5 | B83: CONSTANT_TIER | C83: NAME | D83: string | E83: 5티어 | F83: COLOR | G83: string | H83: |cffff9900
A84: ENUM_ABILITY_UPGRADE_TYPE_RED | B84: CONSTANT_ABILITY_UPGRADE_TYPE | C84: NAME | D84: string | E84: 빨간 파편 | F84: COLOR | G84: string | H84: |cffff3300 | I84: ICON | J84: string | K84: icons\\tooltips\\gem_red.blp
A85: ENUM_ABILITY_UPGRADE_TYPE_BLUE | B85: CONSTANT_ABILITY_UPGRADE_TYPE | C85: NAME | D85: string | E85: 파란 파편 | F85: COLOR | G85: string | H85: |cff0099cc | I85: ICON | J85: string | K85: icons\\tooltips\\gem_blue.blp
A86: ENUM_ABILITY_UPGRADE_TYPE_PURPLE | B86: CONSTANT_ABILITY_UPGRADE_TYPE | C86: NAME | D86: string | E86: 보라 파편 | F86: COLOR | G86: string | H86: |cff990099 | I86: ICON | J86: string | K86: icons\\tooltips\\gem_purple.blp
A87: ENUM_ABILITY_UPGRADE_TYPE_GREEN | B87: CONSTANT_ABILITY_UPGRADE_TYPE | C87: NAME | D87: string | E87: 초록 파편 | F87: COLOR | G87: string | H87: |cff00cc00 | I87: ICON | J87: string | K87: icons\\tooltips\\gem_green.blp
A88: ENUM_ABILITY_UPGRADE_TYPE_ORANGE | B88: CONSTANT_ABILITY_UPGRADE_TYPE | C88: NAME | D88: string | E88: 주황 파편 | F88: COLOR | G88: string | H88: |cffffcc00 | I88: ICON | J88: string | K88: icons\\tooltips\\gem_orange.blp
A89: ENUM_UNIT_CLASS_UNDEAD | B89: CONSTANT_UNIT_CLASS | C89: NAME | D89: string | E89: 언데드 | F89: COLOR | G89: string | H89: |cff00ffff
A90: ENUM_UNIT_CLASS_MECHANICAL | B90: CONSTANT_UNIT_CLASS | C90: NAME | D90: string | E90: 기계 | F90: COLOR | G90: string | H90: |cff00ffff
A91: ENUM_UNIT_CLASS_PLANT | B91: CONSTANT_UNIT_CLASS | C91: NAME | D91: string | E91: 식물 | F91: COLOR | G91: string | H91: |cff00ffff
...

Sheet UnitParams
A1: ID | B1: id | C1: HR00 | D1: HR01 | E1: HR02 | F1: HR03 | G1: HR04 | H1: HR05 | I1: HR06 | J1: HR07 | K1: HR08 | L1: HR09 | M1: HR0a | N1: HR0b | O1: HR0c | P1: HR0d | Q1: HR0e | R1: HR0f | S1: HR0g | T1: SP00 | U1: SP03 | V1: SP04 | W1: SP05 | X1: SP06 | Y1: SP07 | Z1: SP08 | AA1: SP09 | AB1: NP00 | AC1: NP01 | AD1: NP02 | AE1: NP03 | AF1: NP04 | AG1: U000 | AH1: U001 | AI1: U002 | AJ1: U003 | AK1: U004 | AL1: G000 | AM1: G001 | AN1: B000 | AO1: B001
A2: NAME | B2: unitname | C2: 전사 | D2: 총잡이 | E2: 붉은기사 | F2: 어둠추적자 | G2: 흑마법사 | H2: 해병 | I2: 트롤 광전사 | J2: 자객 | K2: 주술사 | L2: 마술사 | M2: 불한당 | N2: 바다사냥꾼 | O2: 주문파괴자 | P2: 기술자 | Q2: 돼지술사 | R2: 요정용 | S2: 성기사 | T2: 군마 | U2: 돼지 | V2: 해골 전사 | W2: 정찰탑 | X2: 전기충격기 | Y2: 늑대정령 | Z2: 고대 코끼리 | AA2: 마법 금고 | AB2: 망각술사 | AC2: 낚시꾼 | AD2: 병참장교 | AE2: 나무꾼 | AF2: 광부 | AG2: 구울 | AH2: 지하마귀 | AI2: 가고일 | AJ2: 강령술사 | AK2: 살덩이 골렘 | AL2: 수호자 | AM2: 생명의 나무 | AN2: 대지령 | AO2: 기계난동꾼
A3: ICON_PATH | B3: iconpath | C3: BTNFootman | D3: BTNRifleMan | E3: BTNUnit_RedFootman | F3: BTNSatyrTrickster | G3: BTNGuldan | H3: BTNMarine | I3: BTNForestTrollTrapper | J3: BTNCultAssassin | K3: BTNShaman | L3: BTNVillagerMan1 | M3: BTNBandit | N3: BTNSeaWitch | O3: BTNSpellBreaker | P3: BTNPeasant | Q3: BTNRazorback | R3: BTNFaerieDragon | S3: BTNTheCaptain | T3: BTNRiderlessHorse | U3: BTNRazorback | V3: BTNSkeletonWarrior | W3: BTNHumanWatchTower | X3: BTNPowerGenerator | Y3: BTNSpiritWolf | Z3: BTNBlackMammoth | AA3: BTNMagicVault | AB3: BTNAcolyte | AC3: BTNHeadhunter | AD3: BTNTheCaptain | AE3: BTNGrunt | AF3: BTNChaosPeon | AG3: BTNGhoul | AH3: BTNCryptFiend | AI3: BTNGargoyle | AJ3: BTNNecromancer | AK3: BTNAbomination | AL3: BTNArmorGolem | AM3: BTNTreeOfEternity | AN3: BTNRockGolem | AO3: BTNROBOGOBLIN
A4: MODEL_PATH | B4: modelpath
A5: INITIAL_ABILITY1 | B5: initialability | C5: {=IF(C6<>"",INDEX(AbilityParams!$1:$1,0,MATCH(C6,AbilityParams!$2:$2,0)),"")} -> 10a0 | D5: {=IF(D6<>"",INDEX(AbilityParams!$1:$1,0,MATCH(D6,AbilityParams!$2:$2,0)),"")} -> 1020 | E5: {=IF(E6<>"",INDEX(AbilityParams!$1:$1,0,MATCH(E6,AbilityParams!$2:$2,0)),"")} -> 1090 | F5: {=IF(F6<>"",INDEX(AbilityParams!$1:$1,0,MATCH(F6,AbilityParams!$2:$2,0)),"")} -> 1070 | G5: {=IF(G6<>"",INDEX(AbilityParams!$1:$1,0,MATCH(G6,AbilityParams!$2:$2,0)),"")} -> 1030 | H5: {=IF(H6<>"",INDEX(AbilityParams!$1:$1,0,MATCH(H6,AbilityParams!$2:$2,0)),"")} -> 10i0 | I5: {=IF(I6<>"",INDEX(AbilityParams!$1:$1,0,MATCH(I6,AbilityParams!$2:$2,0)),"")} -> 10h0 | J5: {=IF(J6<>"",INDEX(AbilityParams!$1:$1,0,MATCH(J6,AbilityParams!$2:$2,0)),"")} -> 1070 | ... R5: {=IF(R6<>"",INDEX(AbilityParams!$1:$1,0,MATCH(R6,AbilityParams!$2:$2,0)),"")} -> 10j0 | S5: 10a0 | T5: {=IF(T6<>"",INDEX(AbilityParams!$1:$1,0,MATCH(T6,AbilityParams!$2:$2,0)),"")} -> 10b0 | U5: {=IF(U6<>"",INDEX(AbilityParams!$1:$1,0,MATCH(U6,AbilityParams!$2:$2,0)),"")} -> 10c0 | V5: {=IF(V6<>"",INDEX(AbilityParams!$1:$1,0,MATCH(V6,AbilityParams!$2:$2,0)),"")} -> 10a0 | W5: {=IF(W6<>"",INDEX(AbilityParams!$1:$1,0,MATCH(W6,AbilityParams!$2:$2,0)),"")} -> 10k0 | X5: {=IF(X6<>"",INDEX(AbilityParams!$1:$1,0,MATCH(X6,AbilityParams!$2:$2,0)),"")} -> 10m0 | Y5: {=IF(Y6<>"",INDEX(AbilityParams!$1:$1,0,MATCH(Y6,AbilityParams!$2:$2,0)),"")} -> 10n0 | Z5: {=IF(Z6<>"",INDEX(AbilityParams!$1:$1,0,MATCH(Z6,AbilityParams!$2:$2,0)),"")} -> 10b0 | AA5: {=IF(AA6<>"",INDEX(AbilityParams!$1:$1,0,MATCH(AA6,AbilityParams!$2:$2,0)),"")} -> 10o0 | ... AM5: {=IF(AM6<>"",INDEX(AbilityParams!$1:$1,0,MATCH(AM6,AbilityParams!$2:$2,0)),"")}
A6: desc | B6: ignore | C6: 조잡한 검 | D6: 구식 저격총 | E6: 곤봉 | F6: 순보 | G6: 화염구 | H6: 가우스 라이플 | I6: 투척용 도끼 | J6: 순보 | K6: 번개 발톱 | L6: 점멸 | M6: 방패 밀어치기 | N6: 그물 던지기 | O6: 역류의 칼날 | P6: 전기충격기 건설 | Q6: 사기의 외침 | R6: 청록의 파동 | S6: 조잡한 검 | T6: 짓밟기 | U6: 뾰족한 가시 | V6: 조잡한 검 | W6: 사냥꾼의 장궁 | X6: 전기충격 | Y6: 번개 발톱 | Z6: 짓밟기 | AA6: 행운의 금화 | AG6: 뛰어들기 | AH6: 끈적거미 | AI6: 치고 빠지기 | AJ6: 암흑의 마법봉 | AK6: 오염된 식칼 | AL6: 방패 밀어치기
A7: INITIAL_ABILITY2 | B7: initialability | C7: {=IF(C8<>"",INDEX(AbilityParams!$1:$1,0,MATCH(C8,AbilityParams!$2:$2,0)),"")} -> 2030 | D7: {=IF(D8<>"",INDEX(AbilityParams!$1:$1,0,MATCH(D8,AbilityParams!$2:$2,0)),"")} -> 20d0 | E7: {=IF(E8<>"",INDEX(AbilityParams!$1:$1,0,MATCH(E8,AbilityParams!$2:$2,0)),"")} -> 20e0 | F7: {=IF(F8<>"",INDEX(AbilityParams!$1:$1,0,MATCH(F8,AbilityParams!$2:$2,0)),"")} -> 20f0 | G7: {=IF(G8<>"",INDEX(AbilityParams!$1:$1,0,MATCH(G8,AbilityParams!$2:$2,0)),"")} -> 2050 | H7: {=IF(H8<>"",INDEX(AbilityParams!$1:$1,0,MATCH(H8,AbilityParams!$2:$2,0)),"")} -> 2000 | I7: {=IF(I8<>"",INDEX(AbilityParams!$1:$1,0,MATCH(I8,AbilityParams!$2:$2,0)),"")} -> 20g0 | J7: {=IF(J8<>"",INDEX(AbilityParams!$1:$1,0,MATCH(J8,AbilityParams!$2:$2,0)),"")} -> 2060 | ... R7: {=IF(R8<>"",INDEX(AbilityParams!$1:$1,0,MATCH(R8,AbilityParams!$2:$2,0)),"")} -> 20h0 | S7: 2030 | T7: {=IF(T8<>"",INDEX(AbilityParams!$1:$1,0,MATCH(T8,AbilityParams!$2:$2,0)),"")} -> 2090 | U7: {=IF(U8<>"",INDEX(AbilityParams!$1:$1,0,MATCH(U8,AbilityParams!$2:$2,0)),"")} -> 2090 | V7: {=IF(V8<>"",INDEX(AbilityParams!$1:$1,0,MATCH(V8,AbilityParams!$2:$2,0)),"")} -> 2030 | W7: {=IF(W8<>"",INDEX(AbilityParams!$1:$1,0,MATCH(W8,AbilityParams!$2:$2,0)),"")} -> 20n0 | X7: {=IF(X8<>"",INDEX(AbilityParams!$1:$1,0,MATCH(X8,AbilityParams!$2:$2,0)),"")} -> 20n0 | Y7: {=IF(Y8<>"",INDEX(AbilityParams!$1:$1,0,MATCH(Y8,AbilityParams!$2:$2,0)),"")} -> 2090 | Z7: {=IF(Z8<>"",INDEX(AbilityParams!$1:$1,0,MATCH(Z8,AbilityParams!$2:$2,0)),"")} -> 2090 | AA7: {=IF(AA8<>"",INDEX(AbilityParams!$1:$1,0,MATCH(AA8,AbilityParams!$2:$2,0)),"")} -> 20n0 | ... AM7: {=IF(AM8<>"",INDEX(AbilityParams!$1:$1,0,MATCH(AM8,AbilityParams!$2:$2,0)),"")}
A8: desc | B8: ignore | C8: 칼날바람 | D8: 회심의 일격 | E8: 도약강타 | F8: 악령의 칼날 | G8: 암흑비전파동 | H8: 전투 자극제 | I8: 광폭화 | J8: 수리검 투척 | K8: 늑대의 상 | L8: 마법 카드패 | M8: 돌진 v2 | N8: 맹독 칼날 | O8: 퇴마의 장막 | P8: 정찰탑 건설 | Q8: 돼지 조련술 | R8: 자연의 결속 | S8: 칼날바람 | T8: 돌진 v2 | U8: 돌진 v2 | V8: 칼날바람 | W8: 보강 | X8: 보강 | Y8: 돌진 v2 | Z8: 돌진 v2 | AA8: 보강 | AC8: 투창 | AG8: 광란 | AH8: 산성 거미줄 | AI8: 그림자 화살 | AJ8: 해골 전사 소환 | AK8: 부패가스 | AL8: 곤봉
A9: ABILITY1 | B9: ability | C9: {=IF(C10<>"",INDEX(AbilityParams!$1:$1,0,MATCH(C10,AbilityParams!$2:$2,0)),"")} -> 20e0 | D9: {=IF(D10<>"",INDEX(AbilityParams!$1:$1,0,MATCH(D10,AbilityParams!$2:$2,0)),"")} | E9: {=IF(E10<>"",INDEX(AbilityParams!$1:$1,0,MATCH(E10,AbilityParams!$2:$2,0)),"")} | F9: {=IF(F10<>"",INDEX(AbilityParams!$1:$1,0,MATCH(F10,AbilityParams!$2:$2,0)),"")} | G9: {=IF(G10<>"",INDEX(AbilityParams!$1:$1,0,MATCH(G10,AbilityParams!$2:$2,0)),"")} | H9: {=IF(H10<>"",INDEX(AbilityParams!$1:$1,0,MATCH(H10,AbilityParams!$2:$2,0)),"")} | I9: {=IF(I10<>"",INDEX(AbilityParams!$1:$1,0,MATCH(I10,AbilityParams!$2:$2,0)),"")} | J9: {=IF(J10<>"",INDEX(AbilityParams!$1:$1,0,MATCH(J10,AbilityParams!$2:$2,0)),"")} | ... R9: {=IF(R10<>"",INDEX(AbilityParams!$1:$1,0,MATCH(R10,AbilityParams!$2:$2,0)),"")} | S9: 20e0 | T9: {=IF(T10<>"",INDEX(AbilityParams!$1:$1,0,MATCH(T10,AbilityParams!$2:$2,0)),"")} | U9: {=IF(U10<>"",INDEX(AbilityParams!$1:$1,0,MATCH(U10,AbilityParams!$2:$2,0)),"")} | V9: {=IF(V10<>"",INDEX(AbilityParams!$1:$1,0,MATCH(V10,AbilityParams!$2:$2,0)),"")} | W9: {=IF(W10<>"",INDEX(AbilityParams!$1:$1,0,MATCH(W10,AbilityParams!$2:$2,0)),"")} | X9: {=IF(X10<>"",INDEX(AbilityParams!$1:$1,0,MATCH(X10,AbilityParams!$2:$2,0)),"")} | Y9: {=IF(Y10<>"",INDEX(AbilityParams!$1:$1,0,MATCH(Y10,AbilityParams!$2:$2,0)),"")} | Z9: {=IF(Z10<>"",INDEX(AbilityParams!$1:$1,0,MATCH(Z10,AbilityParams!$2:$2,0)),"")} | AA9: {=IF(AA10<>"",INDEX(AbilityParams!$1:$1,0,MATCH(AA10,AbilityParams!$2:$2,0)),"")} | ... AM9: {=IF(AM10<>"",INDEX(AbilityParams!$1:$1,0,MATCH(AM10,AbilityParams!$2:$2,0)),"")}
A10: desc | B10: ignore | C10: 도약강타 | S10: 도약강타
A11: ABILITY2 | B11: ability | C11: {=IF(C12<>"",INDEX(AbilityParams!$1:$1,0,MATCH(C12,AbilityParams!$2:$2,0)),"")} | D11: {=IF(D12<>"",INDEX(AbilityParams!$1:$1,0,MATCH(D12,AbilityParams!$2:$2,0)),"")} | E11: {=IF(E12<>"",INDEX(AbilityParams!$1:$1,0,MATCH(E12,AbilityParams!$2:$2,0)),"")} | F11: {=IF(F12<>"",INDEX(AbilityParams!$1:$1,0,MATCH(F12,AbilityParams!$2:$2,0)),"")} | G11: {=IF(G12<>"",INDEX(AbilityParams!$1:$1,0,MATCH(G12,AbilityParams!$2:$2,0)),"")} | H11: {=IF(H12<>"",INDEX(AbilityParams!$1:$1,0,MATCH(H12,AbilityParams!$2:$2,0)),"")} | I11: {=IF(I12<>"",INDEX(AbilityParams!$1:$1,0,MATCH(I12,AbilityParams!$2:$2,0)),"")} | J11: {=IF(J12<>"",INDEX(AbilityParams!$1:$1,0,MATCH(J12,AbilityParams!$2:$2,0)),"")} | ... R11: {=IF(R12<>"",INDEX(AbilityParams!$1:$1,0,MATCH(R12,AbilityParams!$2:$2,0)),"")} | T11: {=IF(T12<>"",INDEX(AbilityParams!$1:$1,0,MATCH(T12,AbilityParams!$2:$2,0)),"")} | U11: {=IF(U12<>"",INDEX(AbilityParams!$1:$1,0,MATCH(U12,AbilityParams!$2:$2,0)),"")} | V11: {=IF(V12<>"",INDEX(AbilityParams!$1:$1,0,MATCH(V12,AbilityParams!$2:$2,0)),"")} | W11: {=IF(W12<>"",INDEX(AbilityParams!$1:$1,0,MATCH(W12,AbilityParams!$2:$2,0)),"")} | X11: {=IF(X12<>"",INDEX(AbilityParams!$1:$1,0,MATCH(X12,AbilityParams!$2:$2,0)),"")} | Y11: {=IF(Y12<>"",INDEX(AbilityParams!$1:$1,0,MATCH(Y12,AbilityParams!$2:$2,0)),"")} | Z11: {=IF(Z12<>"",INDEX(AbilityParams!$1:$1,0,MATCH(Z12,AbilityParams!$2:$2,0)),"")} | AA11: {=IF(AA12<>"",INDEX(AbilityParams!$1:$1,0,MATCH(AA12,AbilityParams!$2:$2,0)),"")} | ... AM11: {=IF(AM12<>"",INDEX(AbilityParams!$1:$1,0,MATCH(AM12,AbilityParams!$2:$2,0)),"")}
A12: desc | B12: ignore | D12: {=IF(D13<>"",INDEX(AbilityParams!$1:$1,0,MATCH(D13,AbilityParams!$2:$2,0)),"")}
A13: ABILITY3 | B13: ability | C13: {=IF(C14<>"",INDEX(AbilityParams!$1:$1,0,MATCH(C14,AbilityParams!$2:$2,0)),"")} | D13: {=IF(D14<>"",INDEX(AbilityParams!$1:$1,0,MATCH(D14,AbilityParams!$2:$2,0)),"")} | E13: {=IF(E14<>"",INDEX(AbilityParams!$1:$1,0,MATCH(E14,AbilityParams!$2:$2,0)),"")} | F13: {=IF(F14<>"",INDEX(AbilityParams!$1:$1,0,MATCH(F14,AbilityParams!$2:$2,0)),"")} | G13: {=IF(G14<>"",INDEX(AbilityParams!$1:$1,0,MATCH(G14,AbilityParams!$2:$2,0)),"")} | H13: {=IF(H14<>"",INDEX(AbilityParams!$1:$1,0,MATCH(H14,AbilityParams!$2:$2,0)),"")} | I13: {=IF(I14<>"",INDEX(AbilityParams!$1:$1,0,MATCH(I14,AbilityParams!$2:$2,0)),"")} | J13: {=IF(J14<>"",INDEX(AbilityParams!$1:$1,0,MATCH(J14,AbilityParams!$2:$2,0)),"")} | ... R13: {=IF(R14<>"",INDEX(AbilityParams!$1:$1,0,MATCH(R14,AbilityParams!$2:$2,0)),"")} | T13: {=IF(T14<>"",INDEX(AbilityParams!$1:$1,0,MATCH(T14,AbilityParams!$2:$2,0)),"")} | U13: {=IF(U14<>"",INDEX(AbilityParams!$1:$1,0,MATCH(U14,AbilityParams!$2:$2,0)),"")} | V13: {=IF(V14<>"",INDEX(AbilityParams!$1:$1,0,MATCH(V14,AbilityParams!$2:$2,0)),"")} | W13: {=IF(W14<>"",INDEX(AbilityParams!$1:$1,0,MATCH(W14,AbilityParams!$2:$2,0)),"")} | X13: {=IF(X14<>"",INDEX(AbilityParams!$1:$1,0,MATCH(X14,AbilityParams!$2:$2,0)),"")} | Y13: {=IF(Y14<>"",INDEX(AbilityParams!$1:$1,0,MATCH(Y14,AbilityParams!$2:$2,0)),"")} | Z13: {=IF(Z14<>"",INDEX(AbilityParams!$1:$1,0,MATCH(Z14,AbilityParams!$2:$2,0)),"")} | AA13: {=IF(AA14<>"",INDEX(AbilityParams!$1:$1,0,MATCH(AA14,AbilityParams!$2:$2,0)),"")} | ... AM13: {=IF(AM14<>"",INDEX(AbilityParams!$1:$1,0,MATCH(AM14,AbilityParams!$2:$2,0)),"")}
A14: desc | B14: ignore
A15: ABILITY4 | B15: ability | C15: {=IF(C16<>"",INDEX(AbilityParams!$1:$1,0,MATCH(C16,AbilityParams!$2:$2,0)),"")} | D15: {=IF(D16<>"",INDEX(AbilityParams!$1:$1,0,MATCH(D16,AbilityParams!$2:$2,0)),"")} | E15: {=IF(E16<>"",INDEX(AbilityParams!$1:$1,0,MATCH(E16,AbilityParams!$2:$2,0)),"")} | F15: {=IF(F16<>"",INDEX(AbilityParams!$1:$1,0,MATCH(F16,AbilityParams!$2:$2,0)),"")} | G15: {=IF(G16<>"",INDEX(AbilityParams!$1:$1,0,MATCH(G16,AbilityParams!$2:$2,0)),"")} | H15: {=IF(H16<>"",INDEX(AbilityParams!$1:$1,0,MATCH(H16,AbilityParams!$2:$2,0)),"")} | I15: {=IF(I16<>"",INDEX(AbilityParams!$1:$1,0,MATCH(I16,AbilityParams!$2:$2,0)),"")} | J15: {=IF(J16<>"",INDEX(AbilityParams!$1:$1,0,MATCH(J16,AbilityParams!$2:$2,0)),"")} | ... R15: {=IF(R16<>"",INDEX(AbilityParams!$1:$1,0,MATCH(R16,AbilityParams!$2:$2,0)),"")} | T15: {=IF(T16<>"",INDEX(AbilityParams!$1:$1,0,MATCH(T16,AbilityParams!$2:$2,0)),"")} | U15: {=IF(U16<>"",INDEX(AbilityParams!$1:$1,0,MATCH(U16,AbilityParams!$2:$2,0)),"")} | V15: {=IF(V16<>"",INDEX(AbilityParams!$1:$1,0,MATCH(V16,AbilityParams!$2:$2,0)),"")} | W15: {=IF(W16<>"",INDEX(AbilityParams!$1:$1,0,MATCH(W16,AbilityParams!$2:$2,0)),"")} | X15: {=IF(X16<>"",INDEX(AbilityParams!$1:$1,0,MATCH(X16,AbilityParams!$2:$2,0)),"")} | Y15: {=IF(Y16<>"",INDEX(AbilityParams!$1:$1,0,MATCH(Y16,AbilityParams!$2:$2,0)),"")} | Z15: {=IF(Z16<>"",INDEX(AbilityParams!$1:$1,0,MATCH(Z16,AbilityParams!$2:$2,0)),"")} | AA15: {=IF(AA16<>"",INDEX(AbilityParams!$1:$1,0,MATCH(AA16,AbilityParams!$2:$2,0)),"")} | ... AM15: {=IF(AM16<>"",INDEX(AbilityParams!$1:$1,0,MATCH(AM16,AbilityParams!$2:$2,0)),"")}
A16: desc | B16: ignore
A17: ABILITY5 | B17: ability | C17: {=IF(C18<>"",INDEX(AbilityParams!$1:$1,0,MATCH(C18,AbilityParams!$2:$2,0)),"")} | D17: {=IF(D18<>"",INDEX(AbilityParams!$1:$1,0,MATCH(D18,AbilityParams!$2:$2,0)),"")} | E17: {=IF(E18<>"",INDEX(AbilityParams!$1:$1,0,MATCH(E18,AbilityParams!$2:$2,0)),"")} | F17: {=IF(F18<>"",INDEX(AbilityParams!$1:$1,0,MATCH(F18,AbilityParams!$2:$2,0)),"")} | G17: {=IF(G18<>"",INDEX(AbilityParams!$1:$1,0,MATCH(G18,AbilityParams!$2:$2,0)),"")} | H17: {=IF(H18<>"",INDEX(AbilityParams!$1:$1,0,MATCH(H18,AbilityParams!$2:$2,0)),"")} | I17: {=IF(I18<>"",INDEX(AbilityParams!$1:$1,0,MATCH(I18,AbilityParams!$2:$2,0)),"")} | J17: {=IF(J18<>"",INDEX(AbilityParams!$1:$1,0,MATCH(J18,AbilityParams!$2:$2,0)),"")} | ... R17: {=IF(R18<>"",INDEX(AbilityParams!$1:$1,0,MATCH(R18,AbilityParams!$2:$2,0)),"")} | T17: {=IF(T18<>"",INDEX(AbilityParams!$1:$1,0,MATCH(T18,AbilityParams!$2:$2,0)),"")} | U17: {=IF(U18<>"",INDEX(AbilityParams!$1:$1,0,MATCH(U18,AbilityParams!$2:$2,0)),"")} | V17: {=IF(V18<>"",INDEX(AbilityParams!$1:$1,0,MATCH(V18,AbilityParams!$2:$2,0)),"")} | W17: {=IF(W18<>"",INDEX(AbilityParams!$1:$1,0,MATCH(W18,AbilityParams!$2:$2,0)),"")} | X17: {=IF(X18<>"",INDEX(AbilityParams!$1:$1,0,MATCH(X18,AbilityParams!$2:$2,0)),"")} | Y17: {=IF(Y18<>"",INDEX(AbilityParams!$1:$1,0,MATCH(Y18,AbilityParams!$2:$2,0)),"")} | Z17: {=IF(Z18<>"",INDEX(AbilityParams!$1:$1,0,MATCH(Z18,AbilityParams!$2:$2,0)),"")} | AA17: {=IF(AA18<>"",INDEX(AbilityParams!$1:$1,0,MATCH(AA18,AbilityParams!$2:$2,0)),"")} | ... AM17: {=IF(AM18<>"",INDEX(AbilityParams!$1:$1,0,MATCH(AM18,AbilityParams!$2:$2,0)),"")}
A18: desc | B18: ignore
A19: ABILITY6 | B19: ability | D19: {=IF(D20<>"",INDEX(AbilityParams!$1:$1,0,MATCH(D20,AbilityParams!$2:$2,0)),"")} | E19: {=IF(E20<>"",INDEX(AbilityParams!$1:$1,0,MATCH(E20,AbilityParams!$2:$2,0)),"")} | F19: {=IF(F20<>"",INDEX(AbilityParams!$1:$1,0,MATCH(F20,AbilityParams!$2:$2,0)),"")} | G19: {=IF(G20<>"",INDEX(AbilityParams!$1:$1,0,MATCH(G20,AbilityParams!$2:$2,0)),"")} | H19: {=IF(H20<>"",INDEX(AbilityParams!$1:$1,0,MATCH(H20,AbilityParams!$2:$2,0)),"")} | I19: {=IF(I20<>"",INDEX(AbilityParams!$1:$1,0,MATCH(I20,AbilityParams!$2:$2,0)),"")} | J19: {=IF(J20<>"",INDEX(AbilityParams!$1:$1,0,MATCH(J20,AbilityParams!$2:$2,0)),"")} | K19: {=IF(K20<>"",INDEX(AbilityParams!$1:$1,0,MATCH(K20,AbilityParams!$2:$2,0)),"")} | ... R19: {=IF(R20<>"",INDEX(AbilityParams!$1:$1,0,MATCH(R20,AbilityParams!$2:$2,0)),"")} | T19: {=IF(T20<>"",INDEX(AbilityParams!$1:$1,0,MATCH(T20,AbilityParams!$2:$2,0)),"")} | U19: {=IF(U20<>"",INDEX(AbilityParams!$1:$1,0,MATCH(U20,AbilityParams!$2:$2,0)),"")} | V19: {=IF(V20<>"",INDEX(AbilityParams!$1:$1,0,MATCH(V20,AbilityParams!$2:$2,0)),"")} | W19: {=IF(W20<>"",INDEX(AbilityParams!$1:$1,0,MATCH(W20,AbilityParams!$2:$2,0)),"")} | X19: {=IF(X20<>"",INDEX(AbilityParams!$1:$1,0,MATCH(X20,AbilityParams!$2:$2,0)),"")} | Y19: {=IF(Y20<>"",INDEX(AbilityParams!$1:$1,0,MATCH(Y20,AbilityParams!$2:$2,0)),"")} | Z19: {=IF(Z20<>"",INDEX(AbilityParams!$1:$1,0,MATCH(Z20,AbilityParams!$2:$2,0)),"")} | AA19: {=IF(AA20<>"",INDEX(AbilityParams!$1:$1,0,MATCH(AA20,AbilityParams!$2:$2,0)),"")} | ... AM19: {=IF(AM20<>"",INDEX(AbilityParams!$1:$1,0,MATCH(AM20,AbilityParams!$2:$2,0)),"")}
A20: desc | B20: ignore
A21: ABILITY7 | B21: ability | C21: {=IF(C22<>"",INDEX(AbilityParams!$1:$1,0,MATCH(C22,AbilityParams!$2:$2,0)),"")} | D21: {=IF(D22<>"",INDEX(AbilityParams!$1:$1,0,MATCH(D22,AbilityParams!$2:$2,0)),"")} | E21: {=IF(E22<>"",INDEX(AbilityParams!$1:$1,0,MATCH(E22,AbilityParams!$2:$2,0)),"")} | F21: {=IF(F22<>"",INDEX(AbilityParams!$1:$1,0,MATCH(F22,AbilityParams!$2:$2,0)),"")} | G21: {=IF(G22<>"",INDEX(AbilityParams!$1:$1,0,MATCH(G22,AbilityParams!$2:$2,0)),"")} | H21: {=IF(H22<>"",INDEX(AbilityParams!$1:$1,0,MATCH(H22,AbilityParams!$2:$2,0)),"")} | I21: {=IF(I22<>"",INDEX(AbilityParams!$1:$1,0,MATCH(I22,AbilityParams!$2:$2,0)),"")} | J21: {=IF(J22<>"",INDEX(AbilityParams!$1:$1,0,MATCH(J22,AbilityParams!$2:$2,0)),"")} | ... R21: {=IF(R22<>"",INDEX(AbilityParams!$1:$1,0,MATCH(R22,AbilityParams!$2:$2,0)),"")} | T21: {=IF(T22<>"",INDEX(AbilityParams!$1:$1,0,MATCH(T22,AbilityParams!$2:$2,0)),"")} | U21: {=IF(U22<>"",INDEX(AbilityParams!$1:$1,0,MATCH(U22,AbilityParams!$2:$2,0)),"")} | V21: {=IF(V22<>"",INDEX(AbilityParams!$1:$1,0,MATCH(V22,AbilityParams!$2:$2,0)),"")} | W21: {=IF(W22<>"",INDEX(AbilityParams!$1:$1,0,MATCH(W22,AbilityParams!$2:$2,0)),"")} | X21: {=IF(X22<>"",INDEX(AbilityParams!$1:$1,0,MATCH(X22,AbilityParams!$2:$2,0)),"")} | Y21: {=IF(Y22<>"",INDEX(AbilityParams!$1:$1,0,MATCH(Y22,AbilityParams!$2:$2,0)),"")} | Z21: {=IF(Z22<>"",INDEX(AbilityParams!$1:$1,0,MATCH(Z22,AbilityParams!$2:$2,0)),"")} | AA21: {=IF(AA22<>"",INDEX(AbilityParams!$1:$1,0,MATCH(AA22,AbilityParams!$2:$2,0)),"")} | ... AM21: {=IF(AM22<>"",INDEX(AbilityParams!$1:$1,0,MATCH(AM22,AbilityParams!$2:$2,0)),"")}
A22: desc | B22: ignore
A23: ABILITY8 | B23: ability | C23: {=IF(C24<>"",INDEX(AbilityParams!$1:$1,0,MATCH(C24,AbilityParams!$2:$2,0)),"")} | D23: {=IF(D24<>"",INDEX(AbilityParams!$1:$1,0,MATCH(D24,AbilityParams!$2:$2,0)),"")} | E23: {=IF(E24<>"",INDEX(AbilityParams!$1:$1,0,MATCH(E24,AbilityParams!$2:$2,0)),"")} | F23: {=IF(F24<>"",INDEX(AbilityParams!$1:$1,0,MATCH(F24,AbilityParams!$2:$2,0)),"")} | G23: {=IF(G24<>"",INDEX(AbilityParams!$1:$1,0,MATCH(G24,AbilityParams!$2:$2,0)),"")} | H23: {=IF(H24<>"",INDEX(AbilityParams!$1:$1,0,MATCH(H24,AbilityParams!$2:$2,0)),"")} | I23: {=IF(I24<>"",INDEX(AbilityParams!$1:$1,0,MATCH(I24,AbilityParams!$2:$2,0)),"")} | J23: {=IF(J24<>"",INDEX(AbilityParams!$1:$1,0,MATCH(J24,AbilityParams!$2:$2,0)),"")} | ... R23: {=IF(R24<>"",INDEX(AbilityParams!$1:$1,0,MATCH(R24,AbilityParams!$2:$2,0)),"")} | T23: {=IF(T24<>"",INDEX(AbilityParams!$1:$1,0,MATCH(T24,AbilityParams!$2:$2,0)),"")} | U23: {=IF(U24<>"",INDEX(AbilityParams!$1:$1,0,MATCH(U24,AbilityParams!$2:$2,0)),"")} | V23: {=IF(V24<>"",INDEX(AbilityParams!$1:$1,0,MATCH(V24,AbilityParams!$2:$2,0)),"")} | W23: {=IF(W24<>"",INDEX(AbilityParams!$1:$1,0,MATCH(W24,AbilityParams!$2:$2,0)),"")} | X23: {=IF(X24<>"",INDEX(AbilityParams!$1:$1,0,MATCH(X24,AbilityParams!$2:$2,0)),"")} | Y23: {=IF(Y24<>"",INDEX(AbilityParams!$1:$1,0,MATCH(Y24,AbilityParams!$2:$2,0)),"")} | Z23: {=IF(Z24<>"",INDEX(AbilityParams!$1:$1,0,MATCH(Z24,AbilityParams!$2:$2,0)),"")} | AA23: {=IF(AA24<>"",INDEX(AbilityParams!$1:$1,0,MATCH(AA24,AbilityParams!$2:$2,0)),"")} | ... AM23: {=IF(AM24<>"",INDEX(AbilityParams!$1:$1,0,MATCH(AM24,AbilityParams!$2:$2,0)),"")}
A24: desc | B24: ignore
A25: TOOLTIP | B25: string | C25: 도내 SSR급 굳건이 | D25: 칼 든 사람보다 무서운 총 든 사람 | E25: 몽둥이가 압권인 전사 | F25: 현실세계에선 스토커였던 내가 이세계에서는 0티어 도적? | G25: 정말로 강한 마법사이다. 왜 강한지는… | H25: 전우애로 똘똘 뭉친 사람 | I25: 트롤인데다 광전사이다. | J25: 벼르고 있는 사람들이 많다. 잡히면 어떻게 될까? | K25: 현실에선 주술이라고는 인디안식 기우제밖에 몰랐지만 여기선 다르다. | L25: [카드값]이 많이 나오는 사람 | M25: 물하기싫으니불한당 | N25: 해녀라고 부르면 화를 낸다. | O25: 마법이 소용없다고 주장하는 사람 | P25: 지상 최강의 막노동꾼 | Q25: 대지마법을 사용할 수 있다는 오해를 자주 산다. | R25: 뀨 | S25: 도내 SSR급 굳건이 | T25: 탑승감 좋은 군마 | U25: 꾸이이익 | V25: 지성도 없고 고통도 모르니 가장 무서운 존재가 아닐까? | W25: 튼튼한 정찰탑 | X25: 이세계에서도 범죄자 소탕에 많이 활용되는 기구 | Y25: 늑대의 형상을 한 정령 | Z25: 싫어하는 학교는 연세대학교 | AA25: 귀엽고 든든한 마법 금고 | AB25: 무슨 설명을 적어놓으려고 했더라? | AC25: 물고기 잡는 법 보다 더 중요한 것은 낚시대를 만드는 법

Sheet BuffParams
A1: ID | B1: ALLOWNULL | C1: fourcc | D1: 10d0 | E1: 10g0 | F1: 10v0 | G1: 10y0 | H1: 10z0 | I1: 10A0 | J1: 2000 | K1: 2070 | L1: 20b0 | M1: 20c0 | N1: 20d0 | O1: 20d1 | P1: 20g0 | Q1: 20h0 | R1: 20h1 | S1: 20j0 | T1: 20k0 | U1: 20n0 | V1: 20o0 | W1: 20p0 | X1: 20s0 | Y1: 3010 | Z1: 3030 | AA1: 3080 | AB1: g000 | AC1: g001
A2: NAME | B2: true | C2: string | D2: 사기의 외침 | E2: 그물 던지기 | F2: 끈적 거미 | G2: 오염된 식칼 | H2: 맑은 물 | I2: 빵 | J2: 전투자극제 | K2: 불붙은 시미터 | L2: 퇴마의 장막 | M2: 맹독 칼날 | N2: 회심의 일격(감속) | O2: 회심의 일격(추뎀) | P2: 광폭화 | Q2: 자연의 결속(캐스터) | R2: 자연의 결속(타겟) | S2: 늑대의 상 | T2: 고대코끼리의 상 | U2: 보강 | V2: 광란 | W2: 산성 거미줄 | X2: 부패가스 | Y2: 감속 | Z2: 전격구체 | AA2: 순보 v2 | AB2: 포만감 | AC2: 포션중독
A3: ICON_PATH | B3: true | C3: iconpath | D3: BTNAbility_Shout1 | E3: BTNEnsnare | F3: BTNAbility_MonsterSpiderCarapace_01 | G3: BTNAbility_storm_ui_icon_stitches_slam | H3: BTNAbility_Water0 | I3: BTNAbility_Pan0 | J3: BTNAbility_terran-stimpack-color | K3: BTNAbility_Gangplank_Passive | L3: BTNSpellBreakerMagicDefend | M3: BTNEnvenomedSpear | N3: BTNAbility_Paladin_SwiftRetribution | O3: BTNAbility_Paladin_SwiftRetribution | P3: BTNBerserkForTrolls | Q3: BTNManaFlare | R3: BTNManaFlare | S3: BTNSpiritWolf | T3: BTNBlackMammoth | U3: BTNAdvStruct | V3: BTNUnholyFrenzy | W3: BTNAbility_Web0 | X3: BTNPlagueCloud | Y3: BTNSlow | Z3: BTNOrbOfLightning | AA3: BTNAbility_SavageStrike
A4: INDIVISUAL | B4: true | C4: integer | D4: 2 | E4: 0 | F4: 1 | G4: 1 | H4: 2 | I4: 2 | J4: 0 | K4: 1 | L4: 0 | M4: 1 | N4: 0 | O4: 0 | P4: 0 | Q4: 2 | R4: 2 | S4: 0 | T4: 0 | U4: 0 | V4: 0 | W4: 0 | X4: 0 | Y4: 1 | Z4: 0 | AA4: 2 | AB4: 2 | AC4: 2
A5: POSITIVE | B5: true | C5: integer | D5: 1 | E5: 0 | F5: 0 | G5: 0 | H5: 1 | I5: 1 | J5: 1 | K5: 0 | L5: 1 | M5: 0 | N5: 0 | O5: 1 | P5: 1 | Q5: 1 | R5: 1 | S5: 1 | T5: 1 | U5: 1 | V5: 1 | W5: 0 | X5: 0 | Y5: 0 | Z5: 1 | AA5: 0 | AB5: 0 | AC5: 0
A6: DISPLAY | B6: true | C6: boolean | D6: true | E6: true | F6: true | G6: true | H6: true | I6: true | J6: true | K6: true | L6: true | M6: true | N6: true | O6: true | P6: true | Q6: true | R6: true | S6: true | T6: true | U6: true | V6: true | W6: true | X6: true | Y6: true | Z6: false | AA6: false | AB6: true | AC6: true
A7: USE_DAMAGE_TAG | B7: true | C7: boolean | D7: false | E7: false | F7: false | G7: false | H7: false | I7: false | J7: false | K7: true | L7: false | M7: true | N7: false | O7: false | P7: false | Q7: false | R7: false | S7: false | T7: false | U7: false | V7: false | W7: false | X7: false | Y7: false | Z7: false | AA7: true | AB7: false | AC7: false
A8: DAMAGE_ID | B8: false | C8: fourcc | K8: 2071 | M8: 20c1 | AA8: 3081
A9: TAG1 | B9: true | C9: abilitytag | K9: FIRE | M9: POISON | AA9: SLASH
A10: TAG2 | B10: true | C10: abilitytag
A11: TAG3 | B11: true | C11: abilitytag
A12: TAG4 | B12: true | C12: abilitytag
A13: NULL | B13: false | C13: real
A14: CAST | B14: false | C14: real
A15: DELAY | B15: false | C15: real
A16: DURATION | B16: false | C16: real | N16: 5.0
A17: RANGE | B17: false | C17: real
A18: RANGE_SECONDARY | B18: false | C18: real
A19: BACKSWING | B19: false | C19: real
A20: RADIUS1 | B20: false | C20: real
A21: RADIUS2 | B21: false | C21: real
A22: RADIUS3 | B22: false | C22: real
A23: ROTSPEED | B23: false | C23: real
A24: STARTAT | B24: false | C24: real
A25: VELO | B25: false | C25: real
A26: INTERVAL | B26: false | C26: real | K26: 0.5 | M26: 0.5 | S26: 0.5 | T26: 0.5
A27: WIDTH | B27: false | C27: real
A28: CHARGE | B28: false | C28: integer
A29: COUNT | B29: false | C29: integer | AA29: 2
A30: TARGET_MAX | B30: false | C30: integer
A31: CHARGE_DURATION | B31: false | C31: real
A32: CHARGE_SPEED | B32: false | C32: real
A33: KNOCKBACK_DISTANCE | B33: false | C33: real
A34: KNOCKBACK_DURATION | B34: false | C34: real
A35: DAMAGE_BASE | B35: false | C35: real | H35: 20.0 | I35: 50.0
A36: DAMAGE_PRIMARY | B36: false | C36: real
A37: DAMAGE_SECONDARY | B37: false | C37: real
A38: DAMAGE_PER_LEVEL | B38: false | C38: real | D38: 0.06 | E38: 0.06 | F38: 0.06 | G38: 0.06 | H38: 0.06 | I38: 0.06 | J38: 0.07 | K38: 0.07 | L38: 0.07 | M38: 0.07 | O38: 0.07 | P38: 0.07 | R38: 0.07 | S38: 0.07 | T38: 0.07 | V38: 0.07 | W38: 0.07 | Y38: 0.08 | AA38: 0.08
A39: DAMAGE_AMPLIFIER1 | B39: false | C39: real | D39: 0.5 | E39: 0.2 | F39: 0.03 | G39: 0.025 | J39: 0.175 | K39: 0.85 | L39: 1.65 | M39: 0.2 | O39: 1.25 | P39: 0.15 | R39: 0.027 | S39: 0.225 | T39: 0.0175 | V39: 0.05 | W39: 0.4 | Y39: 0.02 | AA39: 0.25
A40: DAMAGE_AMPLIFIER2 | B40: false | C40: real | L40: 0.45 | R40: 0.022 | AA40: 0.25
...

Sheet AbilityParams
A1: ID | B1: ALLOWNULL | C1: fourcc | D1: 1000 | E1: 1010 | F1: 1020 | G1: 1030 | H1: 1040 | I1: 1050 | J1: 1060 | K1: 1070 | L1: 1080 | M1: 1090 | N1: 10a0 | O1: 10b0 | P1: 10c0 | Q1: 10d0 | R1: 10e0 | S1: 10f0 | T1: 10g0 | U1: 10h0 | V1: 10i0 | W1: 10j0 | X1: 10k0 | Y1: 10l0 | Z1: 10m0 | AA1: 10n0 | AB1: 10o0 | AC1: 10p0 | AD1: 10q0 | AE1: 10r0 | AF1: 10s0 | AG1: 10t0 | AH1: 10u0 | AI1: 10v0 | AJ1: 10w0 | AK1: 10x0 | AL1: 10y0 | AM1: 10z0 | AN1: 10A0 | AO1: 10B0 | AP1: 10C0 | AQ1: 2000 | AR1: 2030 | AS1: 2040 | AT1: 2050 | AU1: 2060 | AV1: 2070 | AW1: 2080 | AX1: 2090 | AY1: 20a0 | AZ1: 20b0 | BA1: 20c0 | BB1: 20d0 | BC1: 20e0 | BD1: 20f0 | BE1: 20g0 | BF1: 20h0 | BG1: 20i0 | BH1: 20j0 | BI1: 20k0 | BJ1: 20l0 | BK1: 20m0 | BL1: 20n0 | BM1: 20o0 | BN1: 20p0 | BO1: 20q0 | BP1: 20r0 | BQ1: 20s0 | BR1: 3000 | BS1: 3010 | BT1: 3020 | BU1: 3030 | BV1: 3040 | BW1: 3050 | BX1: 3060 | BY1: 3070 | BZ1: 3080 | CA1: 4000 | CB1: 4010 | CC1: 5000 | CD1: 5010 | CE1: C000 | CF1: C001 | CG1: C002 | CH1: C003 | CI1: C004 | CJ1: C005 | CK1: C006 | CL1: C007 | CM1: C008
A2: NAME | B2: true | C2: string | D2: 방패 밀어치기 | E2: 쌍극의 번개 | F2: 구식 저격총 | G2: 화염구 | H2: 연쇄번개 | I2: 신성의 빛 | J2: 점멸 | K2: 순보 | L2: 다중사격 | M2: 곤봉 | N2: 조잡한 검 | O2: 짓밟기 | P2: 뾰족한 가시 | Q2: 사기의 외침 | R2: 박치기 | S2: 역류의 칼날 | T2: 그물 던지기 | U2: 투척용 도끼 | V2: 가우스 라이플 | W2: 청록의 파동 | X2: 사냥꾼의 장궁 | Y2: 전기충격기 건설 | Z2: 전기충격 | AA2: 번개 발톱 | AB2: 행운의 금화 | AC2: 돌진 | AD2: 단검 | AE2: 힘의 장갑 | AF2: 날카로운 갈고리 | AG2: 에메랄드 | AH2: 뛰어들기 | AI2: 끈적거미 | AJ2: 치고 빠지기 | AK2: 암흑의 마법봉 | AL2: 오염된 식칼 | AM2: 맑은 물 | AN2: 빵 | AO2: 행운의 은관 | AP2: 곡괭이 | AQ2: 전투 자극제 | AR2: 칼날바람 | AS2: 마법 카드패 | AT2: 암흑비전파동 | AU2: 수리검 투척 | AV2: 불붙은 시미터 | AW2: 낚시 | AX2: 돌진 v2 | AY2: 돼지 조련술 | AZ2: 퇴마의 장막 | BA2: 맹독 칼날 | BB2: 회심의 일격 | BC2: 도약강타 | BD2: 악령의 칼날 | BE2: 광폭화 | BF2: 자연의 결속 | BG2: 정찰탑 건설 | BH2: 늑대의 상 | BI2: 고대 코끼리의 상 | BJ2: 달빛 글레이브 | BK2: 투창 | BL2: 보강 | BM2: 광란 | BN2: 산성 거미줄 | BO2: 그림자 화살 | BP2: 해골 전사 소환 | BQ2: 부패가스 | BR2: 기관총 난사 | BS2: 감속 | BT2: 착취의 보옥 | BU2: 전격 구체 | BV2: 바람 칼날 | BW2: 강철 군마 | BX2: 갈고리 던지기 | BY2: 용암채찍 | BZ2: 순보 v2 | CA2: 미사일 컨테이너 | CB2: 불사조 | CC2: 화룡의 숨결 | CD2: 종막: 이스보셋 | CE2: 새내기 | CF2: 동인천 역가드 | CG2: 가짜광기 | CH2: 꿈나무 | CI2: 아이돌 | CJ2: 정의의 사도 | CK2: 치유계 | CL2: 패셔니스타 | CM2: 밤의 일족
A3: ICON_PATH | B3: true | C3: iconpath | D3: BTNAbility_Warrior_ShieldBash | E3: btnAbility_protoss-doubleshieldrecharge | F3: BTNDwarvenLongRifle | G3: BTNFireBolt | H3: btnAbility_swarm-kerrigan-chainreaction | I3: BTNHolyBolt | J3: BTNBlink | K3: BTNAbility_SavageStrike | L3: BTNAbility_Multishot | M3: BTNAbility_Mace_10 | N3: BTNSteelMelee | O3: BTNWarStomp | P3: BTNQuillSprayOff | Q3: BTNAbility_Shout1 | R3: BTNDizzy | S3: BTNFeedBack | T3: BTNEnsnare | U3: BTNOrcMeleeUpOne | V3: btnAbility_tychus-weapons-level4 | W3: BTNAbility_Nature_AbolishMagic | X3: BTNImprovedBows | Y3: BTNPowerGenerator | Z3: btnability-protoss-beambounce | AA3: BTNShamanAdept | AB3: BTNMGExchange | AC3: BTNAbility_storm_ui_icon_varian_charge | AD3: BTNAbility_ShortBlade_10 | AE3: BTNGauntletsOfOgrePower | AF3: BTNClawsOfAttack | AG3: BTNGem | AH3: BTNGhoulFrenzy | AI3: BTNAbility_MonsterSpiderCarapace_01 | AJ3: BTNAbility_Shadow_Shadowfury | AK3: BTNWandSkull | AL3: BTNAbility_storm_ui_icon_stitches_slam | AM3: BTNAbility_Water0 | AN3: BTNAbility_Pan0 | AO3: BTNCirclet | AP3: BTNGatherGold | AQ3: BTNAbility_terran-stimpack-color | AR3: BTNWhirlwind | AS3: BTNAbility_PickACard | AT3: BTNAbility_ArchonQ | AU3: BTNAbility_Shuriken | AV3: BTNAbility_Gangplank_Passive | AW3: BTNAbility_Fishingpole | AX3: BTNAbility_storm_ui_icon_varian_charge | AY3: BTNPig | AZ3: BTNSpellBreakerMagicDefend | BA3: BTNEnvenomedSpear | BB3: BTNAbility_Paladin_SwiftRetribution | BC3: BTNAbility_storm_ui_icon_sonya_leap | BD3: BTNAbility_Shadow_RitualOfSacrifice | BE3: BTNBerserkForTrolls | BF3: BTNManaFlare | BG3: BTNHumanWatchTower | BH3: BTNSpiritWolf | BI3: BTNBlackMammoth | BJ3: BTNUpgradeMoonGlaive | BK3: BTNSteelRanged | BL3: BTNAdvStruct | BM3: BTNUnholyFrenzy | BN3: BTNAbility_Web0 | BO3: BTNAbility_Shadow_PainSpike | BP3: BTNSkeletonWarrior | BQ3: BTNPlagueCloud | BR3: BTNFlakCannons | BS3: BTNSlow | BT3: BTNOrbOfDeath | BU3: BTNOrbOfLightning | BV3: BTNAbility_WindBlade0 | BW3: BTNRiderlessHorse | BX3: BTNAbility_storm_ui_icon_stitches_hook | BY3: BTNAbility_LavaSwip | BZ3: BTNAbility_SavageStrike | CA3: BTNClusterRockets | CB3: BTNAbility_storm_ui_icon_kaelthas_phoenix | CC3: BTNAbility_storm_ui_icon_deathwing_molten_flame | CD3: BTNAbility_Isubosete | CE3: BTNMurgalSlave | CF3: BTNSacrifice | CG3: BTNBerserkForTrolls | CH3: BTNAcorn | CI3: BTNSorceress | CJ3: BTNRacoon | CK3: BTNFountainOfLife | CL3: BTNRobeOfTheMagi | CM3: BTNElunesBlessing
A4: TIER | B4: true | C4: integer | D4: 1 | E4: 1 | F4: 1 | G4: 1 | H4: 1 | I4: 1 | J4: 1 | K4: 1 | L4: 1 | M4: 1 | N4: 1 | O4: 1 | P4: 1 | Q4: 1 | R4: 1 | S4: 1 | T4: 1 | U4: 1 | V4: 1 | W4: 1 | X4: 1 | Y4: 1 | Z4: 1 | AA4: 1 | AB4: 1 | AC4: 1 | AD4: 1 | AE4: 1 | AF4: 1 | AG4: 1 | AH4: 1 | AI4: 1 | AJ4: 1 | AK4: 1 | AL4: 1 | AM4: 1 | AN4: 1 | AO4: 1 | AP4: 1 | AQ4: 2 | AR4: 2 | AS4: 2 | AT4: 2 | AU4: 2 | AV4: 2 | AW4: 2 | AX4: 2 | AY4: 2 | AZ4: 2 | BA4: 2 | BB4: 2 | BC4: 2 | BD4: 2 | BE4: 2 | BF4: 2 | BG4: 2 | BH4: 2 | BI4: 2 | BJ4: 2 | BK4: 2 | BL4: 2 | BM4: 2 | BN4: 2 | BO4: 2 | BP4: 2 | BQ4: 2 | BR4: 3 | BS4: 3 | BT4: 3 | BU4: 3 | BV4: 3 | BW4: 3 | BX4: 3 | BY4: 3 | BZ4: 3 | CA4: 4 | CB4: 4 | CC4: 5 | CD4: 5 | CE4: 0 | CF4: 0 | CG4: 0 | CH4: 0 | CI4: 0 | CJ4: 0 | CK4: 0 | CL4: 0 | CM4: 0
A5: COST | B5: true | C5: integer | D5: 1 | E5: 1 | F5: 1 | G5: 1 | H5: 1 | I5: 1 | J5: 1 | K5: 1 | L5: 1 | M5: 1 | N5: 1 | O5: 1 | P5: 1 | Q5: 1 | R5: 1 | S5: 1 | T5: 1 | U5: 1 | V5: 1 | W5: 1 | X5: 1 | Y5: 1 | Z5: 1 | AA5: 1 | AB5: 1 | AC5: 1 | AD5: 1 | AE5: 1 | AF5: 1 | AG5: 1 | AH5: 1 | AI5: 1 | AJ5: 1 | AK5: 1 | AL5: 1 | AM5: 1 | AN5: 1 | AO5: 1 | AP5: 1 | AQ5: 2 | AR5: 2 | AS5: 2 | AT5: 2 | AU5: 2 | AV5: 2 | AW5: 2 | AX5: 2 | AY5: 2 | AZ5: 2 | BA5: 2 | BB5: 2 | BC5: 2 | BD5: 2 | BE5: 2 | BF5: 2 | BG5: 2 | BH5: 2 | BI5: 2 | BJ5: 2 | BK5: 2 | BL5: 2 | BM5: 2 | BN5: 2 | BO5: 2 | BP5: 2 | BQ5: 2 | BR5: 3 | BS5: 3 | BT5: 3 | BU5: 3 | BV5: 3 | BW5: 3 | BX5: 3 | BY5: 3 | BZ5: 3 | CA5: 4 | CB5: 4 | CC5: 5 | CD5: 5 | CE5: 0 | CF5: 0 | CG5: 0 | CH5: 0 | CI5: 0 | CJ5: 0 | CK5: 0 | CL5: 0 | CM5: 0
A6: CAST_TYPE | B6: true | C6: casttype | D6: TARGET_LOCATION | E6: DRAG_TO_USE | F6: WEAPON | G6: TARGET_LOCATION | H6: TARGET_UNIT | I6: WEAPON | J6: TARGET_LOCATION | K6: TARGET_LOCATION | L6: TARGET_LOCATION | M6: WEAPON | N6: WEAPON | O6: WEAPON | P6: WEAPON | Q6: IMMEDIATE | R6: WEAPON | S6: WEAPON | T6: TARGET_LOCATION | U6: WEAPON | V6: WEAPON | W6: IMMEDIATE | X6: WEAPON | Y6: TARGET_LOCATION | Z6: WEAPON | AA6: WEAPON | AB6: WEAPON | AC6: TARGET_LOCATION | AD6: WEAPON | AE6: PASSIVE | AF6: PASSIVE | AG6: PASSIVE | AH6: TARGET_UNIT | AI6: WEAPON | AJ6: TARGET_UNIT | AK6: WEAPON | AL6: WEAPON | AM6: IMMEDIATE | AN6: IMMEDIATE | AO6: PASSIVE | AP6: WEAPON | AQ6: IMMEDIATE | AR6: IMMEDIATE | AS6: WEAPON | AT6: TARGET_LOCATION | AU6: TARGET_LOCATION | AV6: WEAPON | AW6: TARGET_LOCATION | AX6: TARGET_LOCATION | AY6: WEAPON | AZ6: IMMEDIATE | BA6: WEAPON | BB6: IMMEDIATE | BC6: TARGET_LOCATION | BD6: WEAPON | BE6: IMMEDIATE | BF6: TARGET_UNIT | BG6: TARGET_LOCATION | BH6: IMMEDIATE | BI6: IMMEDIATE | BJ6: WEAPON | BK6: WEAPON | BL6: IMMEDIATE | BM6: IMMEDIATE | BN6: TARGET_LOCATION | BO6: WEAPON | BP6: TARGET_LOCATION | BQ6: PASSIVE | BR6: TARGET_LOCATION | BS6: TARGET_LOCATION | BT6: WEAPON | BU6: WEAPON | BV6: WEAPON | BW6: TARGET_LOCATION | BX6: TARGET_LOCATION | BY6: WEAPON | BZ6: TARGET_LOCATION | CA6: TARGET_LOCATION | CB6: DRAG_TO_USE | CC6: TARGET_LOCATION | CD6: TARGET_LOCATION | CE6: PASSIVE | CF6: PASSIVE | CG6: PASSIVE | CH6: PASSIVE | CI6: PASSIVE | CJ6: PASSIVE | CK6: PASSIVE | CL6: PASSIVE | CM6: PASSIVE
A7: TAG1 | B7: true | C7: abilitytag | D7: BASH | E7: LIGHTNING | F7: FIREARM | G7: FIRE | H7: LIGHTNING | I7: DIVINE | K7: SLASH | L7: PIERCE | M7: BASH | N7: NORMAL | O7: BASH | P7: BIO | R7: BASH | S7: SLASH | U7: NORMAL | V7: FIREARM | W7: NATURE | X7: PIERCE | Y7: SUMMON | Z7: LIGHTNING | AA7: NORMAL | AC7: BASH | AD7: SLASH | AH7: NORMAL | AI7: BIO | AJ7: NORMAL | AK7: DARK | AL7: BASH | AM7: FOOD | AN7: FOOD | AP7: BASH | AR7: NORMAL | AS7: THROW | AT7: DARK | AU7: THROW | AV7: FIRE | AX7: BASH | AY7: SUMMON | BA7: SLASH | BC7: BASH | BD7: SLASH | BF7: NATURE | BG7: SERVANT | BH7: TRANSFORM | BI7: TRANSFORM | BJ7: THROW | BK7: THROW | BN7: BIO | BO7: DARK | BP7: SUMMON | BQ7: BIO | BR7: FIREARM | BT7: DARK | BU7: LIGHTNING | BV7: SLASH | BW7: SERVANT | BX7: NORMAL | BY7: FIRE | BZ7: SLASH | CA7: FIREARM | CB7: FIRE | CC7: FIRE | CD7: FIREARM | CE7: CHINGHO | CF7: CHINGHO | CG7: CHINGHO | CH7: CHINGHO | CI7: CHINGHO | CJ7: CHINGHO | CK7: CHINGHO | CL7: CHINGHO | CM7: CHINGHO
A8: TAG2 | B8: true | C8: abilitytag | F8: PIERCE | N8: SLASH | P8: PIERCE | U8: THROW | V8: PIERCE | AA8: LIGHTNING | AD8: PIERCE | AL8: POISON | AR8: SLASH | AV8: SLASH | BA8: POISON | BD8: DARK | BJ8: NORMAL | BK8: PIERCE | BN8: POISON | BO8: SUMMON | BQ8: POISON | BR8: PIERCE | BV8: WIND | BX8: THROW | CA8: EXPLOSION | CD8: PIERCE
A9: TAG3 | B9: true | C9: abilitytag | AA9: WILD | CD9: DARK
A10: TAG4 | B10: true | C10: abilitytag
A11: COOLDOWN_MAX | B11: true | C11: real | D11: 8.0 | E11: 6.7 | F11: 0.0 | G11: 5.5 | H11: 5.3 | I11: 0.0 | J11: 30.0 | K11: 6.0 | L11: 3.5 | M11: 0.0 | N11: 0.0 | O11: 0.0 | P11: 0.0 | Q11: 12.0 | R11: 0.0 | S11: 0.0 | T11: 10.0 | U11: 0.0 | V11: 0.0 | W11: 3.0 | X11: 0.0 | Y11: 4.0 | Z11: 0.0 | AA11: 0.0 | AB11: 0.0 | AC11: 9.0 | AD11: 0.0 | AE11: 0.0 | AF11: 0.0 | AG11: 0.0 | AH11: 6.5 | AI11: 0.0 | AJ11: 10.0 | AK11: 0.0 | AL11: 0.0 | AM11: 1.5 | AN11: 1.5 | AO11: 0.0 | AP11: 0.0 | AQ11: 10.0 | AR11: 0.0 | AS11: 0.0 | AT11: 5.25 | AU11: 1.5 | AV11: 0.0 | AW11: 1.5 | AX11: 9.0 | AY11: 0.0 | AZ11: 9.0 | BA11: 0.0 | BB11: 5.0 | BC11: 8.0 | BD11: 0.0 | BE11: 10.0 | BF11: 1.5 | BG11: 4.0 | BH11: 1.5 | BI11: 1.5 | BJ11: 0.0 | BK11: 0.0 | BL11: 10.0 | BM11: 5.0 | BN11: 10.0 | BO11: 0.0 | BP11: 10.0 | BQ11: 0.0 | BR11: 8.0 | BS11: 10.0 | BT11: 0.0 | BU11: 0.0 | BV11: 0.0 | BW11: 0.0 | BX11: 10.0 | BY11: 0.0 | BZ11: 6.0 | CA11: 12.0 | CB11: 9.0 | CC11: 10.0 | CD11: 0.0 | CE11: 0.0 | CF11: 0.0 | CG11: 0.0 | CH11: 0.0 | CI11: 0.0 | CJ11: 0.0 | CK11: 0.0 | CL11: 0.0 | CM11: 0.0
A12: COOLDOWN_MIN | B12: true | C12: real | D12: 2.0 | E12: 0.5 | F12: 0.0 | G12: 0.5 | H12: 0.5 | I12: 0.0 | J12: 0.0 | K12: 0.5 | L12: 0.5 | M12: 0.0 | N12: 0.0 | O12: 0.0 | P12: 0.0 | Q12: 6.0 | R12: 0.0 | S12: 0.0 | T12: 5.0 | U12: 0.0 | V12: 0.0 | W12: 3.0 | X12: 0.0 | Y12: 2.0 | Z12: 0.0 | AA12: 0.0 | AB12: 0.0 | AC12: 2.0 | AD12: 0.0 | AE12: 0.0 | AF12: 0.0 | AG12: 0.0 | AH12: 0.5 | AI12: 0.0 | AJ12: 4.0 | AK12: 0.0 | AL12: 0.0 | AM12: 1.5 | AN12: 1.5 | AO12: 0.0 | AP12: 0.0 | AQ12: 2.0 | AR12: 0.0 | AS12: 0.0 | AT12: 5.0 | AU12: 1.5 | AV12: 0.0 | AW12: 1.5 | AX12: 2.0 | AY12: 0.0 | AZ12: 2.0 | BA12: 0.0 | BB12: 1.75 | BC12: 4.0 | BD12: 0.0 | BE12: 2.0 | BF12: 1.5 | BG12: 4.0 | BH12: 1.5 | BI12: 1.5 | BJ12: 0.0 | BK12: 0.0 | BL12: 5.0 | BM12: 5.0 | BN12: 5.0 | BO12: 0.0 | BP12: 3.0 | BQ12: 0.0 | BR12: 1.5 | BS12: 4.0 | BT12: 0.0 | BU12: 0.0 | BV12: 0.0 | BW12: 0.0 | BX12: 3.3 | BY12: 0.0 | BZ12: 0.5 | CA12: 2.0 | CB12: 3.0 | CC12: 5.0 | CD12: 0.0 | CE12: 0.0 | CF12: 0.0 | CG12: 0.0 | CH12: 0.0 | CI12: 0.0 | CJ12: 0.0 | CK12: 0.0 | CL12: 0.0 | CM12: 0.0
A13: MANACOST | B13: true | C13: integer | D13: 25 | E13: 27 | F13: 0 | G13: 25 | H13: 22 | I13: 0 | J13: 20 | K13: 45 | L13: 15 | M13: 0 | N13: 0 | O13: 0 | P13: 0 | Q13: 38 | R13: 0 | S13: 0 | T13: 27 | U13: 0 | V13: 0 | W13: 20 | X13: 0 | Y13: 10 | Z13: 0 | AA13: 0 | AB13: 0 | AC13: 30 | AD13: 0 | AE13: 0 | AF13: 0 | AG13: 0 | AH13: 20 | AI13: 0 | AJ13: 17 | AK13: 0 | AL13: 0 | AM13: 0 | AN13: 0 | AO13: 0 | AP13: 0 | AQ13: 35 | AR13: 19 | AS13: 0 | AT13: 25 | AU13: 3 | AV13: 0 | AW13: 0 | AX13: 25 | AY13: 0 | AZ13: 30 | BA13: 0 | BB13: 15 | BC13: 25 | BD13: 0 | BE13: 35 | BF13: 10 | BG13: 30 | BH13: 20 | BI13: 20 | BJ13: 0 | BK13: 0 | BL13: 17 | BM13: 30 | BN13: 20 | BO13: 0 | BP13: 50 | BQ13: 0 | BR13: 26 | BS13: 30 | BT13: 0 | BU13: 0 | BV13: 0 | BW13: 0 | BX13: 31 | BY13: 0 | BZ13: 45 | CA13: 50 | CB13: 55 | CC13: 85 | CD13: 125 | CE13: 0 | CF13: 0 | CG13: 0 | CH13: 0 | CI13: 0 | CJ13: 0 | CK13: 0 | CL13: 0 | CM13: 0
A14: CAST | B14: false | C14: real | E14: 0.25 | Y14: 0.5 | AW14: 0.2 | BG14: 4.0 | BS14: 0.25 | CB14: 0.25 | CC14: 0.75 | CD14: 0.8
A15: DELAY | B15: false | C15: real | E15: 0.65 | F15: 2.0 | G15: 0.2 | H15: 0.2 | L15: 0.2 | Q15: 0.22 | T15: 0.2 | AT15: 0.5 | AU15: 0.25 | BG15: 0.75 | BK15: 0.5 | BN15: 0.2 | BP15: 0.2 | CA15: 0.2 | CB15: 0.5
A16: DURATION | B16: false | C16: real | Q16: 8.0 | T16: 4.0 | Y16: 10.0 | AI16: 4.0 | AJ16: 0.55 | AL16: 4.0 | AM16: 20.0 | AN16: 20.0 | AO16: 30.0 | AQ16: 5.0 | AT16: 2.5 | AV16: 5.0 | AY16: 5.0 | AZ16: 9.0 | BA16: 5.0 | BB16: 1.5 | BC16: 0.5 | BD16: 3.0 | BE16: 4.0 | BL16: 3.5 | BM16: 3.0 | BN16: 5.0 | BO16: 3.0 | BP16: 15.0 | BQ16: 1.5 | BS16: 4.5 | BU16: 2.0 | BZ16: 4.0 | CA16: 3.0
A17: RANGE | B17: false | C17: real | E17: 500. | G17: 750. | H17: 575.0 | J17: 600.0 | K17: 500.0 | L17: 725.0 | T17: 800.0 | AH17: 500.0 | AJ17: 600.0 | AT17: 450.0 | AU17: 575.0 | AW17: 600.0 | BC17: 550.0 | BJ17: 450.0 | BN17: 800.0 | BP17: 800.0 | BR17: 750.0 | BS17: 800.0 | BT17: 800.0 | BX17: 1000.0 | BY17: 300.0 | BZ17: 500.0 | CA17: 1200.0 | CB17: 800.0 | CC17: 800.0 | CD17: 1250.0
A18: RANGE_SECONDARY | B18: false | C18: real | H18: 575.0 | V18: 150.0 | Z18: 415.0 | AH18: 100.0 | AJ18: 500.0 | AT18: 1000.0 | CB18: 1500.0
A19: BACKSWING | B19: false | C19: real | D19: 0.15 | F19: 0.25 | G19: 0.15 | H19: 0.15 | L19: 0.15 | P19: 0.25 | T19: 0.15 | U19: 0.25 | V19: 0.25 | X19: 0.25 | AC19: 0.15 | AH19: 0.15 | AI19: 0.25 | AK19: 0.25 | AP19: 0.25 | AS19: 0.25 | AT19: 0.25 | AU19: 0.15 | AX19: 0.15 | BJ19: 0.25 | BK19: 0.5 | BN19: 0.15 | BO19: 0.25 | BP19: 0.15 | BR19: 0.15 | BS19: 0.15 | BU19: 0.25 | BV19: 0.25 | BY19: 0.25 | CA19: 0.15 | CD19: 0.2
A20: RADIUS1 | B20: false | C20: real | Q20: 450. | W20: 225.0 | AR20: 200.0 | BY20: 65.0
A21: RADIUS2 | B21: false | C21: real | D21: 75.0 | G21: 65.0 | L21: 32.5 | T21: 55.0 | V21: 55.0 | AC21: 75.0 | AT21: 80.0 | AU21: 55.0 | AX21: 75.0 | BN21: 55.0 | BP21: 65.0 | BR21: 65.0 | BX21: 65.0 | CA21: 65.0 | CD21: 50.0
A22: RADIUS3 | B22: false | C22: real | G22: 145.0 | K22: 65.0 | Y22: 100.0 | BC22: 175.0 | BG22: 100.0 | BQ22: 200.0 | BS22: 200.0 | BZ22: 65.0 | CA22: 500.0 | CB22: 200.0 | CC22: 250.0
A23: ROTSPEED | B23: false | C23: real | Q23: 6.0 | AR23: 6.0
A24: STARTAT | B24: false | C24: real | F24: 45.0 | G24: 32.5 | L24: 32.5 | P24: 25.0 | T24: 28.5 | U24: 25.0 | V24: 25.0 | X24: 25.0 | AB24: 45.0 | AI24: 25.0 | AK24: 25.0 | AS24: 25.0 | AU24: 35.0 | BJ24: 25.0 | BK24: 25.0 | BN24: 28.5 | BO24: 25.0 | BP24: 32.5 | BR24: 32.5 | BU24: 25.0 | BV24: 25.0 | BX24: 25.0 | BY24: 65.0 | CA24: 32.5 | CD24: 35.0
A25: VELO | B25: false | C25: real | F25: 1875.0 | G25: 1100.0 | L25: 1400.0 | P25: 1485.0 | T25: 1100.0 | U25: 1485.0 | V25: 1550.0 | X25: 1485.0 | AB25: 1375.0 | AH25: 1500.0 | AI25: 900.0 | AJ25: 2560.0 | AK25: 1200.0 | AS25: 1250.0 | AU25: 1250.0 | BF25: 1080.0 | BJ25: 1150.0 | BK25: 1200.0 | BN25: 1100.0 | BO25: 1050.0 | BR25: 1875.0 | BU25: 1250.0 | BV25: 1600.0 | BX25: 1350.0 | CA25: 400.0 | CB25: 1500.0 | CD25: 2000.0
A26: INTERVAL | B26: false | C26: real | H26: 0.15 | Q26: 0.25 | Z26: 0.15 | AR26: 0.25 | AU26: 0.15 | BQ26: 0.5 | BR26: 0.125 | BS26: 0.5 | BT26: 0.25 | CA26: 0.125 | CC26: 0.2 | CD26: 0.125
A27: WIDTH | B27: false | C27: real | L27: 30.0 | BY27: 150.0 | CD27: 30.0
A28: CHARGE | B28: false | C28: integer | AU28: 3
A29: COUNT | B29: false | C29: integer | L29: 5 | Q29: 8 | AR29: 8 | AS29: 4 | AU29: 3 | AV29: 3 | BP29: 1 | BQ29: 8 | BR29: 10 | BS29: 10 | BY29: 3 | CA29: 20 | CC29: 15 | CD29: 4
A30: TARGET_MAX | B30: false | C30: integer | H30: 4 | Z30: 4 | BJ30: 3
A31: CHARGE_DURATION | B31: false | C31: real | D31: 0.25 | AC31: 0.5 | AX31: 0.5 | BK31: 0.25
A32: CHARGE_SPEED | B32: false | C32: real | D32: 1250.0 | AC32: 1200.0 | AX32: 1200.0 | BK32: 0.5
A33: KNOCKBACK_DISTANCE | B33: false | C33: real | D33: 100.0
A34: KNOCKBACK_DURATION | B34: false | C34: real | D34: 0.5
A35: UNIT_ID1 | B35: false | C35: fourcc | Y35: SP06 | AY35: SP03 | BG35: SP05 | BP35: SP04 | BW35: SP00
A36: UNIT_ID2 | B36: false | C36: fourcc
A37: UNIT_ID3 | B37: false | C37: fourcc
A38: UNIT_ID4 | B38: false | C38: fourcc
A39: BUFF_ID1 | B39: false | C39: fourcc | Q39: 10d0 | T39: 10g0 | AI39: 10v0 | AL39: 10y0 | AM39: 10z0 | AN39: 10A0 | AQ39: 2000 | AV39: 2070 | AZ39: 20b0 | BA39: 20c0 | BB39: 20d0 | BE39: 20g0 | BF39: 20h0 | BH39: 20j0 | BI39: 20k0 | BL39: 20n0 | BM39: 20o0 | BN39: 20p0 | BQ39: 20s0 | BS39: 3010 | BU39: 3030 | BZ39: 3080
A40: BUFF_DESCRIPTION1 | B40: false | C40: ignore | Q40: 체젠,공증 | T40: 감속 | AI40: 감속 | AL40: 체력감소 | AM40: 마나회복 | AN40: 체력회복 | AQ40: 강화 | AV40: 지속피해 | AZ40: 쉴드 | BA40: 지속피해 | BB40: 감속 | BE40: 광폭화 | BF40: 캐스터 | BH40: 변신 | BI40: 변신 | BL40: 방마저 증가 | BM40: 광폭화 | BN40: 감속 | BQ40: 지속피해 | BS40: 감속 | BU40: 이속증가 | BZ40: 추가타
...

Sheet AbilityMix
A1: ID1 | B1: NAME1 | C1: ="+" -> + | D1: ID2 | E1: NAME2 | F1: ="=" -> = | G1: RESULT | H1: NAME
A2: {=INDEX(AbilityParams!$1:$1,0,MATCH(B2,AbilityParams!$2:$2,0))} -> 10a0 | B2: 조잡한 검 | C2: ="+" -> + | D2: {=INDEX(AbilityParams!$1:$1,0,MATCH(E2,AbilityParams!$2:$2,0))} -> 1030 | E2: 화염구 | F2: ="=" -> = | G2: {=INDEX(AbilityParams!$1:$1,0,MATCH(H2,AbilityParams!$2:$2,0))} -> 2070 | H2: 불붙은 시미터
A3: {=INDEX(AbilityParams!$1:$1,0,MATCH(B3,AbilityParams!$2:$2,0))} -> 10p0 | B3: 돌진 | C3: ="+" -> + | D3: {=INDEX(AbilityParams!$1:$1,0,MATCH(E3,AbilityParams!$2:$2,0))} -> 10e0 | E3: 박치기 | F3: ="=" -> = | G3: {=INDEX(AbilityParams!$1:$1,0,MATCH(H3,AbilityParams!$2:$2,0))} -> 2090 | H3: 돌진 v2
A4: {=INDEX(AbilityParams!$1:$1,0,MATCH(B4,AbilityParams!$2:$2,0))} -> 10s0 | B4: 날카로운 갈고리 | C4: ="+" -> + | D4: {=INDEX(AbilityParams!$1:$1,0,MATCH(E4,AbilityParams!$2:$2,0))} -> 1080 | E4: 다중사격 | F4: ="=" -> = | G4: {=INDEX(AbilityParams!$1:$1,0,MATCH(H4,AbilityParams!$2:$2,0))} -> 2060 | H4: 수리검 투척
A5: {=INDEX(AbilityParams!$1:$1,0,MATCH(B5,AbilityParams!$2:$2,0))} -> 10s0 | B5: 날카로운 갈고리 | C5: ="+" -> + | D5: {=INDEX(AbilityParams!$1:$1,0,MATCH(E5,AbilityParams!$2:$2,0))} -> 10a0 | E5: 조잡한 검 | F5: ="=" -> = | G5: {=INDEX(AbilityParams!$1:$1,0,MATCH(H5,AbilityParams!$2:$2,0))} -> 2030 | H5: 칼날바람
A6: {=INDEX(AbilityParams!$1:$1,0,MATCH(B6,AbilityParams!$2:$2,0))} -> 10q0 | B6: 단검 | C6: ="+" -> + | D6: {=INDEX(AbilityParams!$1:$1,0,MATCH(E6,AbilityParams!$2:$2,0))} -> 10w0 | E6: 치고 빠지기 | F6: ="=" -> = | G6: {=INDEX(AbilityParams!$1:$1,0,MATCH(H6,AbilityParams!$2:$2,0))} -> 20f0 | H6: 악령의 칼날
A7: {=INDEX(AbilityParams!$1:$1,0,MATCH(B7,AbilityParams!$2:$2,0))} -> 10p0 | B7: 돌진 | C7: ="+" -> + | D7: {=INDEX(AbilityParams!$1:$1,0,MATCH(E7,AbilityParams!$2:$2,0))} -> 10b0 | E7: 짓밟기 | F7: ="=" -> = | G7: {=INDEX(AbilityParams!$1:$1,0,MATCH(H7,AbilityParams!$2:$2,0))} -> 20e0 | H7: 도약강타
A8: {=INDEX(AbilityParams!$1:$1,0,MATCH(B8,AbilityParams!$2:$2,0))} -> 10i0 | B8: 가우스 라이플 | C8: ="+" -> + | D8: {=INDEX(AbilityParams!$1:$1,0,MATCH(E8,AbilityParams!$2:$2,0))} -> 2060 | E8: 수리검 투척 | F8: ="=" -> = | G8: {=INDEX(AbilityParams!$1:$1,0,MATCH(H8,AbilityParams!$2:$2,0))} -> 3000 | H8: 기관총 난사
A9: {=INDEX(AbilityParams!$1:$1,0,MATCH(B9,AbilityParams!$2:$2,0))} -> 1020 | B9: 구식 저격총 | C9: ="+" -> + | D9: {=INDEX(AbilityParams!$1:$1,0,MATCH(E9,AbilityParams!$2:$2,0))} -> 2060 | E9: 수리검 투척 | F9: ="=" -> = | G9: {=INDEX(AbilityParams!$1:$1,0,MATCH(H9,AbilityParams!$2:$2,0))} -> 3000 | H9: 기관총 난사
A10: {=INDEX(AbilityParams!$1:$1,0,MATCH(B10,AbilityParams!$2:$2,0))} -> 10r0 | B10: 힘의 장갑 | C10: ="+" -> + | D10: {=INDEX(AbilityParams!$1:$1,0,MATCH(E10,AbilityParams!$2:$2,0))} -> 20m0 | E10: 투창 | F10: ="=" -> = | G10: {=INDEX(AbilityParams!$1:$1,0,MATCH(H10,AbilityParams!$2:$2,0))} -> 3060 | H10: 갈고리 던지기
A11: {=INDEX(AbilityParams!$1:$1,0,MATCH(B11,AbilityParams!$2:$2,0))} -> 1070 | B11: 순보 | C11: + | D11: {=INDEX(AbilityParams!$1:$1,0,MATCH(E11,AbilityParams!$2:$2,0))} -> 20f0 | E11: 악령의 칼날 | F11: ="=" -> = | G11: {=INDEX(AbilityParams!$1:$1,0,MATCH(H11,AbilityParams!$2:$2,0))} -> 3080 | H11: 순보 v2
A12: {=INDEX(AbilityParams!$1:$1,0,MATCH(B12,AbilityParams!$2:$2,0))} -> 3000 | B12: 기관총 난사 | C12: ="+" -> + | D12: {=INDEX(AbilityParams!$1:$1,0,MATCH(E12,AbilityParams!$2:$2,0))} -> 1030 | E12: 화염구 | F12: ="=" -> = | G12: {=INDEX(AbilityParams!$1:$1,0,MATCH(H12,AbilityParams!$2:$2,0))} -> 4000 | H12: 미사일 컨테이너

Sheet AbilityTable
A1: index | B1: abilityId | C1: name | D1: enabled | E1: initialWeight
A2: ENUM_ABILITY_TABLE_TIER_1 | B2: {=INDEX(AbilityParams!$1:$1,0,MATCH(C2,AbilityParams!$2:$2,0))} -> 1000 | C2: 방패 밀어치기 | D2: FALSE | E2: 1
A3: ENUM_ABILITY_TABLE_TIER_1 | B3: {=INDEX(AbilityParams!$1:$1,0,MATCH(C3,AbilityParams!$2:$2,0))} -> 1010 | C3: 쌍극의 번개 | D3: FALSE | E3: 1
A4: ENUM_ABILITY_TABLE_TIER_1 | B4: {=INDEX(AbilityParams!$1:$1,0,MATCH(C4,AbilityParams!$2:$2,0))} -> 1020 | C4: 구식 저격총 | D4: FALSE | E4: 1
A5: ENUM_ABILITY_TABLE_TIER_1 | B5: {=INDEX(AbilityParams!$1:$1,0,MATCH(C5,AbilityParams!$2:$2,0))} -> 1030 | C5: 화염구 | D5: FALSE | E5: 1
A6: ENUM_ABILITY_TABLE_TIER_1 | B6: {=INDEX(AbilityParams!$1:$1,0,MATCH(C6,AbilityParams!$2:$2,0))} -> 1040 | C6: 연쇄번개 | D6: FALSE | E6: 1
A7: ENUM_ABILITY_TABLE_TIER_1 | B7: {=INDEX(AbilityParams!$1:$1,0,MATCH(C7,AbilityParams!$2:$2,0))} -> 1050 | C7: 신성의 빛 | D7: TRUE | E7: 1
A8: ENUM_ABILITY_TABLE_TIER_1 | B8: {=INDEX(AbilityParams!$1:$1,0,MATCH(C8,AbilityParams!$2:$2,0))} -> 1060 | C8: 점멸 | D8: FALSE | E8: 1
A9: ENUM_ABILITY_TABLE_TIER_1 | B9: {=INDEX(AbilityParams!$1:$1,0,MATCH(C9,AbilityParams!$2:$2,0))} -> 1070 | C9: 순보 | D9: FALSE | E9: 1
A10: ENUM_ABILITY_TABLE_TIER_1 | B10: {=INDEX(AbilityParams!$1:$1,0,MATCH(C10,AbilityParams!$2:$2,0))} -> 1080 | C10: 다중사격 | D10: FALSE | E10: 1
A11: ENUM_ABILITY_TABLE_TIER_1 | B11: {=INDEX(AbilityParams!$1:$1,0,MATCH(C11,AbilityParams!$2:$2,0))} -> 1090 | C11: 곤봉 | D11: TRUE | E11: 1
A12: ENUM_ABILITY_TABLE_TIER_1 | B12: {=INDEX(AbilityParams!$1:$1,0,MATCH(C12,AbilityParams!$2:$2,0))} -> 10a0 | C12: 조잡한 검 | D12: TRUE | E12: 1
A13: ENUM_ABILITY_TABLE_TIER_1 | B13: {=INDEX(AbilityParams!$1:$1,0,MATCH(C13,AbilityParams!$2:$2,0))} -> 10b0 | C13: 짓밟기 | D13: FALSE | E13: 1
... A75: ENUM_ABILITY_TABLE_TIER_5 | B75: {=INDEX(AbilityParams!$1:$1,0,MATCH(C75,AbilityParams!$2:$2,0))} -> 5010 | C75: 종막: 이스보셋 | D75: TRUE | E75: 1

Sheet AbilityTooltips
A1: {=INDEX(AbilityParams!$1:$1,0,MATCH(B1,AbilityParams!$2:$2,0))} -> 1000 | B1: 방패 밀어치기 | C1: 지정한 방향으로 약진하여 충돌하는 대상과 대상 주변의 적들에게 <cstring:DAMAGE_COLOR,DAMAGE_TYPE/><real:2,2><prop:DAMAGE_AMPLIFIER1/>*<statValue:DAMAGE_STAT1/>*(1+<prop:DAMAGE_PER_LEVEL/>*<skillLevel/>)</real>|r<shift:DAMAGE_STAT1/>의 피해를 입히고 밀쳐냅니다. 가장 가까운 적에게는 <cstring:STAT_COLOR,$STAT_CONSTANT/><percent:DAMAGE_PRIMARY/>|r의 피해를 입힙니다.
A2: {=INDEX(AbilityParams!$1:$1,0,MATCH(B2,AbilityParams!$2:$2,0))} -> 1010 | B2: 쌍극의 번개 | C2: 지정 범위 내의 적들에게 <cstring:DAMAGE_COLOR,DAMAGE_TYPE/><real:2,2><prop:DAMAGE_AMPLIFIER1/>*<statValue:DAMAGE_STAT1/>*(1+<prop:DAMAGE_PER_LEVEL/>*<skillLevel/>)</real>|r<shift:DAMAGE_STAT1/>의 피해를 입힙니다.
A3: {=INDEX(AbilityParams!$1:$1,0,MATCH(B3,AbilityParams!$2:$2,0))} -> 1020 | B3: 구식 저격총 | C3: <cstring:STAT_COLOR,$STAT_CONSTANT/><second:DELAY/>|r 동안 정신집중 후 대상에게 <cstring:DAMAGE_COLOR,DAMAGE_TYPE/><real:2,2><prop:DAMAGE_AMPLIFIER1/>*<statValue:DAMAGE_STAT1/>*<statValue:DAMAGE_STAT2/>*(1+<prop:DAMAGE_PER_LEVEL/>*<skillLevel/>)</real>|r<shift:DAMAGE_STAT1/>의 피해를 입힙니다.<br/><br/><cstring:STAT_COLOR,#999999/>고정된 공격속도를 가집니다.|r
